<sdf version='1.7'>
  <world name='default'>
    <light name='sun' type='directional'>
      <cast_shadows>1</cast_shadows>
      <pose>0 0 10 0 -0 0</pose>
      <diffuse>0.8 0.8 0.8 1</diffuse>
      <specular>0.2 0.2 0.2 1</specular>
      <attenuation>
        <range>1000</range>
        <constant>0.9</constant>
        <linear>0.01</linear>
        <quadratic>0.001</quadratic>
      </attenuation>
      <direction>-0.5 0.1 -0.9</direction>
      <spot>
        <inner_angle>0</inner_angle>
        <outer_angle>0</outer_angle>
        <falloff>0</falloff>
      </spot>
    </light>
    <model name='ground_plane'>
      <static>1</static>
      <link name='link'>
        <collision name='collision'>
          <geometry>
            <plane>
              <normal>0 0 1</normal>
              <size>100 100</size>
            </plane>
          </geometry>
          <surface>
            <friction>
              <ode>
                <mu>100</mu>
                <mu2>50</mu2>
              </ode>
              <torsional>
                <ode/>
              </torsional>
            </friction>
            <contact>
              <ode/>
            </contact>
            <bounce/>
          </surface>
          <max_contacts>10</max_contacts>
        </collision>
        <visual name='visual'>
          <cast_shadows>0</cast_shadows>
          <geometry>
            <plane>
              <normal>0 0 1</normal>
              <size>100 100</size>
            </plane>
          </geometry>
          <material>
            <script>
              <uri>file://media/materials/scripts/gazebo.material</uri>
              <name>Gazebo/Grey</name>
            </script>
          </material>
        </visual>
        <self_collide>0</self_collide>
        <enable_wind>0</enable_wind>
        <kinematic>0</kinematic>
      </link>
    </model>
    <gravity>0 0 -9.8</gravity>
    <magnetic_field>6e-06 2.3e-05 -4.2e-05</magnetic_field>
    <atmosphere type='adiabatic'/>
    <physics type='ode'>
      <max_step_size>0.001</max_step_size>
      <real_time_factor>1</real_time_factor>
      <real_time_update_rate>1000</real_time_update_rate>
      <solver>
        <type>quick</type>
        <iters>200</iters>
        <sor>1.3</sor>
      </solver>
      <constraints>
        <cfm>0.0</cfm>
        <erp>0.2</erp>
      </constraints>
    </physics>
    <scene>
      <ambient>0.4 0.4 0.4 1</ambient>
      <background>0.7 0.7 0.7 1</background>
      <shadows>1</shadows>
    </scene>
    <audio>
      <device>default</device>
    </audio>
    <wind/>
    <spherical_coordinates>
      <surface_model>EARTH_WGS84</surface_model>
      <latitude_deg>0</latitude_deg>
      <longitude_deg>0</longitude_deg>
      <elevation>0</elevation>
      <heading_deg>0</heading_deg>
    </spherical_coordinates>
    <model name='sort_robotic_arm'>
      <link name='ground_link'>
        <inertial>
          <pose>0.011375 -1.86413 1.79743 0 -0 0</pose>
          <mass>0.4868</mass>
          <inertia>
            <ixx>2.29682</ixx>
            <ixy>-0.0101959</ixy>
            <ixz>0.00793771</ixz>
            <iyy>2.33883</iyy>
            <iyz>0.823136</iyz>
            <izz>2.36484</izz>
          </inertia>
        </inertial>
        <collision name='ground_link_fixed_joint_lump__base_link_collision'>
          <pose>0 0 0.28 0 -0 0</pose>
          <geometry>
            <cylinder>
              <length>0.56</length>
              <radius>0.60625</radius>
            </cylinder>
          </geometry>
          <surface>
            <contact>
              <ode/>
            </contact>
            <friction>
              <ode/>
              <torsional>
                <ode/>
              </torsional>
            </friction>
            <bounce/>
          </surface>
          <max_contacts>10</max_contacts>
        </collision>
        <collision name='ground_link_fixed_joint_lump__servo1_link_collision_1'>
          <pose>0.087 -0.0229 0.364 0 -0 0</pose>
          <geometry>
            <box>
              <size>0.558 0.205 0.474</size>
            </box>
          </geometry>
          <surface>
            <contact>
              <ode/>
            </contact>
            <friction>
              <ode/>
              <torsional>
                <ode/>
              </torsional>
            </friction>
            <bounce/>
          </surface>
          <max_contacts>10</max_contacts>
        </collision>
        <collision name='ground_link_fixed_joint_lump__left_tower_link_collision_2'>
          <pose>2 -3 2 3.14159 1.57079 3.14159</pose>
          <geometry>
            <box>
              <size>4 0.2 0.2</size>
            </box>
          </geometry>
          <surface>
            <contact>
              <ode/>
            </contact>
            <friction>
              <ode/>
              <torsional>
                <ode/>
              </torsional>
            </friction>
            <bounce/>
          </surface>
          <max_contacts>10</max_contacts>
        </collision>
        <collision name='ground_link_fixed_joint_lump__right_tower_link_collision_3'>
          <pose>-2 -3 2 3.14159 1.57079 3.14159</pose>
          <geometry>
            <box>
              <size>4 0.2 0.2</size>
            </box>
          </geometry>
          <surface>
            <contact>
              <ode/>
            </contact>
            <friction>
              <ode/>
              <torsional>
                <ode/>
              </torsional>
            </friction>
            <bounce/>
          </surface>
          <max_contacts>10</max_contacts>
        </collision>
        <collision name='ground_link_fixed_joint_lump__up_tower_link_collision_4'>
          <pose>0 -3 4.1 0 -0 0</pose>
          <geometry>
            <box>
              <size>4 0.2 0.2</size>
            </box>
          </geometry>
          <surface>
            <contact>
              <ode/>
            </contact>
            <friction>
              <ode/>
              <torsional>
                <ode/>
              </torsional>
            </friction>
            <bounce/>
          </surface>
          <max_contacts>10</max_contacts>
        </collision>
        <collision name='ground_link_fixed_joint_lump__camera_link_collision_5'>
          <pose>0 -3 3.95 1.57159 1.57079 3.14159</pose>
          <geometry>
            <box>
              <size>0.1 0.1 0.2</size>
            </box>
          </geometry>
          <surface>
            <contact>
              <ode/>
            </contact>
            <friction>
              <ode/>
              <torsional>
                <ode/>
              </torsional>
            </friction>
            <bounce/>
          </surface>
          <max_contacts>10</max_contacts>
        </collision>
        <visual name='ground_link_fixed_joint_lump__base_link_visual'>
          <pose>-0.60625 0.60625 0 1.57 -0 0</pose>
          <geometry>
            <mesh>
              <scale>0.01 0.01 0.01</scale>
              <uri>model://sort_robotic_arm_description/meshes/Arm_Base/Base.STL</uri>
            </mesh>
          </geometry>
          <material>
            <script>
              <name>Gazebo/Yellow</name>
              <uri>file://media/materials/scripts/gazebo.material</uri>
            </script>
          </material>
        </visual>
        <visual name='ground_link_fixed_joint_lump__servo1_link_visual_1'>
          <pose>0.1025 0.1825 0.12 0 -0 3.14</pose>
          <geometry>
            <mesh>
              <scale>0.01 0.01 0.01</scale>
              <uri>model://sort_robotic_arm_description/meshes/Servos/Servo_MG996R.STL</uri>
            </mesh>
          </geometry>
          <material>
            <script>
              <name>Gazebo/Gray</name>
              <uri>file://media/materials/scripts/gazebo.material</uri>
            </script>
          </material>
        </visual>
        <visual name='ground_link_fixed_joint_lump__left_tower_link_visual_2'>
          <pose>2 -3 2 3.14159 1.57079 3.14159</pose>
          <geometry>
            <box>
              <size>4 0.2 0.2</size>
            </box>
          </geometry>
          <material>
            <script>
              <name>Gazebo/Blue</name>
              <uri>file://media/materials/scripts/gazebo.material</uri>
            </script>
          </material>
        </visual>
        <visual name='ground_link_fixed_joint_lump__right_tower_link_visual_3'>
          <pose>-2 -3 2 3.14159 1.57079 3.14159</pose>
          <geometry>
            <box>
              <size>4 0.2 0.2</size>
            </box>
          </geometry>
          <material>
            <script>
              <name>Gazebo/Blue</name>
              <uri>file://media/materials/scripts/gazebo.material</uri>
            </script>
          </material>
        </visual>
        <visual name='ground_link_fixed_joint_lump__up_tower_link_visual_4'>
          <pose>0 -3 4.1 0 -0 0</pose>
          <geometry>
            <box>
              <size>4 0.2 0.2</size>
            </box>
          </geometry>
          <material>
            <script>
              <name>Gazebo/Blue</name>
              <uri>file://media/materials/scripts/gazebo.material</uri>
            </script>
          </material>
        </visual>
        <visual name='ground_link_fixed_joint_lump__camera_link_visual_5'>
          <pose>0 -3 3.95 1.57159 1.57079 3.14159</pose>
          <geometry>
            <box>
              <size>0.1 0.1 0.2</size>
            </box>
          </geometry>
          <material>
            <script>
              <name>Gazebo/Red</name>
              <uri>file://media/materials/scripts/gazebo.material</uri>
            </script>
          </material>
        </visual>
        <sensor name='camera' type='camera'>
          <visualize>1</visualize>
          <update_rate>10</update_rate>
          <camera>
            <horizontal_fov>1.0856</horizontal_fov>
            <image>
              <width>640</width>
              <height>480</height>
              <format>R8G8B8</format>
            </image>
            <clip>
              <near>0.1</near>
              <far>10</far>
            </clip>
          </camera>
          <plugin name='camera_controller' filename='libgazebo_ros_camera.so'>
            <frame_name>camera_optical_frame</frame_name>
          </plugin>
          <pose>0 -3 3.95 3.14159 1.57079 -1.57159</pose>
        </sensor>
        <self_collide>0</self_collide>
        <enable_wind>0</enable_wind>
        <kinematic>0</kinematic>
      </link>
      <joint name='servo1_waist_joint' type='revolute'>
        <pose relative_to='ground_link'>0 0 0.56 0 -0 0</pose>
        <parent>ground_link</parent>
        <child>waist_link</child>
        <axis>
          <xyz>0 0 1</xyz>
          <limit>
            <lower>-1e+16</lower>
            <upper>1e+16</upper>
          </limit>
          <dynamics>
            <spring_reference>0</spring_reference>
            <spring_stiffness>0</spring_stiffness>
          </dynamics>
        </axis>
      </joint>
      <link name='waist_link'>
        <pose relative_to='servo1_waist_joint'>0 0 0 0 -0 0</pose>
        <inertial>
          <pose>-0.085569 -0.042339 0.150536 0 -0 0</pose>
          <mass>0.16067</mass>
          <inertia>
            <ixx>0.104657</ixx>
            <ixy>-0.000887275</ixy>
            <ixz>-0.00152183</ixz>
            <iyy>0.0136117</iyy>
            <iyz>-0.00726861</iyz>
            <izz>0.0822322</izz>
          </inertia>
        </inertial>
        <collision name='waist_link_collision'>
          <pose>0 0 0.08 0 -0 0</pose>
          <geometry>
            <cylinder>
              <length>0.16</length>
              <radius>0.485</radius>
            </cylinder>
          </geometry>
          <surface>
            <contact>
              <ode/>
            </contact>
            <friction>
              <ode/>
              <torsional>
                <ode/>
              </torsional>
            </friction>
            <bounce/>
          </surface>
          <max_contacts>10</max_contacts>
        </collision>
        <collision name='waist_link_fixed_joint_lump__servo2_link_collision_1'>
          <pose>-0.216 -0.106876 0.258051 0.785 -0 0</pose>
          <geometry>
            <box>
              <size>0.558 0.205 0.474</size>
            </box>
          </geometry>
          <surface>
            <contact>
              <ode/>
            </contact>
            <friction>
              <ode/>
              <torsional>
                <ode/>
              </torsional>
            </friction>
            <bounce/>
          </surface>
          <max_contacts>10</max_contacts>
        </collision>
        <visual name='waist_link_visual'>
          <pose>-0.485 -0.485 0 0 -0 0</pose>
          <geometry>
            <mesh>
              <scale>0.01 0.01 0.01</scale>
              <uri>model://sort_robotic_arm_description/meshes/Arm_Base/Waist.STL</uri>
            </mesh>
          </geometry>
          <material>
            <script>
              <name>Gazebo/Yellow</name>
              <uri>file://media/materials/scripts/gazebo.material</uri>
            </script>
          </material>
        </visual>
        <visual name='waist_link_fixed_joint_lump__servo2_link_visual_1'>
          <pose>-0.41 -0.186347 0.593754 -1.57 0.785796 -1.56967</pose>
          <geometry>
            <mesh>
              <scale>0.01 0.01 0.01</scale>
              <uri>model://sort_robotic_arm_description/meshes/Servos/Servo_MG996R.STL</uri>
            </mesh>
          </geometry>
          <material>
            <script>
              <name>Gazebo/Gray</name>
              <uri>file://media/materials/scripts/gazebo.material</uri>
            </script>
          </material>
        </visual>
        <self_collide>0</self_collide>
        <enable_wind>0</enable_wind>
        <kinematic>0</kinematic>
      </link>
      <joint name='servo2_arm1_joint' type='revolute'>
        <pose relative_to='waist_link'>0.068 -0.138396 0.392743 -1.57 -0.785796 1.56967</pose>
        <parent>waist_link</parent>
        <child>arm1_link</child>
        <axis>
          <xyz>0 0 1</xyz>
          <limit>
            <lower>-0.785</lower>
            <upper>0.785</upper>
            <effort>10</effort>
            <velocity>1</velocity>
          </limit>
          <dynamics>
            <spring_reference>0</spring_reference>
            <spring_stiffness>0</spring_stiffness>
          </dynamics>
        </axis>
      </joint>
      <link name='arm1_link'>
        <pose relative_to='servo2_arm1_joint'>0 0 0 0 -0 0</pose>
        <inertial>
          <pose>0.025 -0.63 -0.05 1.57 -0 0</pose>
          <mass>0.05231</mass>
          <inertia>
            <ixx>0.01</ixx>
            <ixy>0</ixy>
            <ixz>0</ixz>
            <iyy>6e-05</iyy>
            <iyz>0</iyz>
            <izz>0.01</izz>
          </inertia>
        </inertial>
        <collision name='arm1_link_collision'>
          <pose>0.025 -0.63 -0.05 1.57 -0 0</pose>
          <geometry>
            <cylinder>
              <length>1.62</length>
              <radius>0.21</radius>
            </cylinder>
          </geometry>
          <surface>
            <contact>
              <ode/>
            </contact>
            <friction>
              <ode/>
              <torsional>
                <ode/>
              </torsional>
            </friction>
            <bounce/>
          </surface>
          <max_contacts>10</max_contacts>
        </collision>
        <visual name='arm1_link_visual'>
          <pose>0.3125 0.21 -0.23 0 0 -3.14</pose>
          <geometry>
            <mesh>
              <scale>0.01 0.01 0.01</scale>
              <uri>model://sort_robotic_arm_description/meshes/Arm_Base/Arm1.STL</uri>
            </mesh>
          </geometry>
          <material>
            <script>
              <name>Gazebo/Yellow</name>
              <uri>file://media/materials/scripts/gazebo.material</uri>
            </script>
          </material>
        </visual>
        <self_collide>0</self_collide>
        <enable_wind>0</enable_wind>
        <kinematic>0</kinematic>
      </link>
      <joint name='arm1_servo3_joint' type='revolute'>
        <pose relative_to='arm1_link'>0 -1.2 0 0 -0 0</pose>
        <parent>arm1_link</parent>
        <child>servo3_link</child>
        <axis>
          <xyz>0 0 1</xyz>
          <limit>
            <lower>-2</lower>
            <upper>0</upper>
            <effort>10</effort>
            <velocity>1</velocity>
          </limit>
          <dynamics>
            <spring_reference>0</spring_reference>
            <spring_stiffness>0</spring_stiffness>
          </dynamics>
        </axis>
      </joint>
      <link name='servo3_link'>
        <pose relative_to='arm1_servo3_joint'>0 0 0 0 -0 0</pose>
        <inertial>
          <pose>-0 -0.195596 0.182399 0 -0 1.57</pose>
          <mass>0.12811</mass>
          <inertia>
            <ixx>0.0184931</ixx>
            <ixy>-2.10122e-06</ixy>
            <ixz>-0.000549903</ixz>
            <iyy>0.0131317</iyy>
            <iyz>-4.37902e-07</iyz>
            <izz>0.0127816</izz>
          </inertia>
        </inertial>
        <collision name='servo3_link_collision'>
          <pose>0 -0.1 0.237 0 -0 1.57</pose>
          <geometry>
            <box>
              <size>0.558 0.205 0.474</size>
            </box>
          </geometry>
          <surface>
            <contact>
              <ode/>
            </contact>
            <friction>
              <ode/>
              <torsional>
                <ode/>
              </torsional>
            </friction>
            <bounce/>
          </surface>
          <max_contacts>10</max_contacts>
        </collision>
        <collision name='servo3_link_fixed_joint_lump__arm2_link_collision_1'>
          <pose>0 -0.349785 0.135557 3.14 -0 0</pose>
          <geometry>
            <box>
              <size>0.38 1.15 0.27</size>
            </box>
          </geometry>
          <surface>
            <contact>
              <ode/>
            </contact>
            <friction>
              <ode/>
              <torsional>
                <ode/>
              </torsional>
            </friction>
            <bounce/>
          </surface>
          <max_contacts>10</max_contacts>
        </collision>
        <collision name='servo3_link_fixed_joint_lump__micro_servo1_link_collision_2'>
          <pose>-8e-05 -0.049841 0.100079 1.57159 -0.000796 -1.5708</pose>
          <geometry>
            <box>
              <size>0.326 0.124 0.299</size>
            </box>
          </geometry>
          <surface>
            <contact>
              <ode/>
            </contact>
            <friction>
              <ode/>
              <torsional>
                <ode/>
              </torsional>
            </friction>
            <bounce/>
          </surface>
          <max_contacts>10</max_contacts>
        </collision>
        <visual name='servo3_link_visual'>
          <pose>-0.1025 0.1825 0.474 3.14 -0 0</pose>
          <geometry>
            <mesh>
              <scale>0.01 0.01 0.01</scale>
              <uri>model://sort_robotic_arm_description/meshes/Servos/Servo_MG996R.STL</uri>
            </mesh>
          </geometry>
          <material>
            <script>
              <name>Gazebo/Gray</name>
              <uri>file://media/materials/scripts/gazebo.material</uri>
            </script>
          </material>
        </visual>
        <visual name='servo3_link_fixed_joint_lump__arm2_link_visual_1'>
          <pose>-0.19 0.252885 0.241598 3.14 -0 0</pose>
          <geometry>
            <mesh>
              <scale>0.01 0.01 0.01</scale>
              <uri>model://sort_robotic_arm_description/meshes/Arm_Base/Arm2.STL</uri>
            </mesh>
          </geometry>
          <material>
            <script>
              <name>Gazebo/Yellow</name>
              <uri>file://media/materials/scripts/gazebo.material</uri>
            </script>
          </material>
        </visual>
        <visual name='servo3_link_fixed_joint_lump__micro_servo1_link_visual_2'>
          <pose>0.119908 -0.664316 0.116154 -1.5692 1.57079 -3.14159</pose>
          <geometry>
            <mesh>
              <scale>0.01 0.01 0.01</scale>
              <uri>model://sort_robotic_arm_description/meshes/Servos/Micro_Servo.STL</uri>
            </mesh>
          </geometry>
          <material>
            <script>
              <name>Gazebo/Blue</name>
              <uri>file://media/materials/scripts/gazebo.material</uri>
            </script>
          </material>
        </visual>
        <self_collide>0</self_collide>
        <enable_wind>0</enable_wind>
        <kinematic>0</kinematic>
      </link>
      <joint name='micro_servo1_arm3_joint' type='revolute'>
        <pose relative_to='servo3_link'>0.049908 -0.922316 0.116509 0.001593 0.001593 -3.14159</pose>
        <parent>servo3_link</parent>
        <child>arm3_link</child>
        <axis>
          <xyz>0 1 0</xyz>
          <limit>
            <lower>-1e+16</lower>
            <upper>1e+16</upper>
          </limit>
          <dynamics>
            <spring_reference>0</spring_reference>
            <spring_stiffness>0</spring_stiffness>
          </dynamics>
        </axis>
      </joint>
      <link name='arm3_link'>
        <pose relative_to='micro_servo1_arm3_joint'>0 0 0 0 -0 0</pose>
        <inertial>
          <pose>0 0.206915 0 -1.57 0 0</pose>
          <mass>0.03345</mass>
          <inertia>
            <ixx>0.000145564</ixx>
            <ixy>-4.24871e-11</ixy>
            <ixz>6.94665e-06</ixz>
            <iyy>0.000132564</iyy>
            <iyz>-5.53956e-08</iyz>
            <izz>4.50001e-05</izz>
          </inertia>
        </inertial>
        <collision name='arm3_link_collision'>
          <pose>0 0.2 0 -1.57 0 0</pose>
          <geometry>
            <box>
              <size>0.28 0.33 0.46</size>
            </box>
          </geometry>
          <surface>
            <contact>
              <ode/>
            </contact>
            <friction>
              <ode/>
              <torsional>
                <ode/>
              </torsional>
            </friction>
            <bounce/>
          </surface>
          <max_contacts>10</max_contacts>
        </collision>
        <collision name='arm3_link_fixed_joint_lump__micro_servo2_link_collision_1'>
          <pose>0 0.218 0 1.57 -0 1.57</pose>
          <geometry>
            <box>
              <size>0.326 0.124 0.299</size>
            </box>
          </geometry>
          <surface>
            <contact>
              <ode/>
            </contact>
            <friction>
              <ode/>
              <torsional>
                <ode/>
              </torsional>
            </friction>
            <bounce/>
          </surface>
          <max_contacts>10</max_contacts>
        </collision>
        <visual name='arm3_link_visual'>
          <pose>-0.14 0 0.215 -1.57 0 0</pose>
          <geometry>
            <mesh>
              <scale>0.01 0.01 0.01</scale>
              <uri>model://sort_robotic_arm_description/meshes/Arm_Base/Arm3.STL</uri>
            </mesh>
          </geometry>
          <material>
            <script>
              <name>Gazebo/Yellow</name>
              <uri>file://media/materials/scripts/gazebo.material</uri>
            </script>
          </material>
        </visual>
        <visual name='arm3_link_fixed_joint_lump__micro_servo2_link_visual_1'>
          <pose>-0.098 0.34 0.055 3.14159 1.57079 3.14159</pose>
          <geometry>
            <mesh>
              <scale>0.01 0.01 0.01</scale>
              <uri>model://sort_robotic_arm_description/meshes/Servos/Micro_Servo.STL</uri>
            </mesh>
          </geometry>
          <material>
            <script>
              <name>Gazebo/Blue</name>
              <uri>file://media/materials/scripts/gazebo.material</uri>
            </script>
          </material>
        </visual>
        <self_collide>0</self_collide>
        <enable_wind>0</enable_wind>
        <kinematic>0</kinematic>
      </link>
      <joint name='micro_servo2_gripper_base_joint' type='revolute'>
        <pose relative_to='arm3_link'>0.165 0.28 0.05 0.001593 -0.001593 3.14159</pose>
        <parent>arm3_link</parent>
        <child>gripper_base_link</child>
        <axis>
          <xyz>1 0 0</xyz>
          <limit>
            <lower>-1e+16</lower>
            <upper>1e+16</upper>
          </limit>
          <dynamics>
            <spring_reference>0</spring_reference>
            <spring_stiffness>0</spring_stiffness>
          </dynamics>
        </axis>
      </joint>
      <link name='gripper_base_link'>
        <pose relative_to='micro_servo2_gripper_base_joint'>0 0 0 0 -0 0</pose>
        <inertial>
          <pose>0.148902 -0.317617 0 0 -0 0</pose>
          <mass>0.03416</mass>
          <inertia>
            <ixx>0.000183162</ixx>
            <ixy>0.000129211</ixy>
            <ixz>5.5e-06</ixz>
            <iyy>0.000265474</iyy>
            <iyz>1.6e-05</iyz>
            <izz>0.000415636</izz>
          </inertia>
        </inertial>
        <collision name='gripper_base_link_collision'>
          <pose>0.1 -0.28 0 0 -0 0</pose>
          <geometry>
            <box>
              <size>0.533 0.77 0.24</size>
            </box>
          </geometry>
          <surface>
            <contact>
              <ode/>
            </contact>
            <friction>
              <ode/>
              <torsional>
                <ode/>
              </torsional>
            </friction>
            <bounce/>
          </surface>
          <max_contacts>10</max_contacts>
        </collision>
        <collision name='gripper_base_link_fixed_joint_lump__micro_servo3_link_collision_1'>
          <pose>0.23 -0.38 0 0 -0 0</pose>
          <geometry>
            <box>
              <size>0.326 0.124 0.299</size>
            </box>
          </geometry>
          <surface>
            <contact>
              <ode/>
            </contact>
            <friction>
              <ode/>
              <torsional>
                <ode/>
              </torsional>
            </friction>
            <bounce/>
          </surface>
          <max_contacts>10</max_contacts>
        </collision>
        <visual name='gripper_base_link_visual'>
          <pose>-0.14 -0.63 -0.14 0 -0 0</pose>
          <geometry>
            <mesh>
              <scale>0.01 0.01 0.01</scale>
              <uri>model://sort_robotic_arm_description/meshes/Arm_Gripper/Gripper_Base.STL</uri>
            </mesh>
          </geometry>
          <material>
            <script>
              <name>Gazebo/Yellow</name>
              <uri>file://media/materials/scripts/gazebo.material</uri>
            </script>
          </material>
        </visual>
        <visual name='gripper_base_link_fixed_joint_lump__micro_servo3_link_visual_1'>
          <pose>0.117 -0.38 -0.1037 0 -0 1.57</pose>
          <geometry>
            <mesh>
              <scale>0.01 0.01 0.01</scale>
              <uri>model://sort_robotic_arm_description/meshes/Servos/Micro_Servo.STL</uri>
            </mesh>
          </geometry>
          <material>
            <script>
              <name>Gazebo/Blue</name>
              <uri>file://media/materials/scripts/gazebo.material</uri>
            </script>
          </material>
        </visual>
        <self_collide>0</self_collide>
        <enable_wind>0</enable_wind>
        <kinematic>0</kinematic>
      </link>
      <joint name='gripper_base_down_left_gripper_link_joint' type='revolute'>
        <pose relative_to='gripper_base_link'>-0.01 -0.58 0.02 0 0 -0.1</pose>
        <parent>gripper_base_link</parent>
        <child>down_left_gripper_link_link</child>
        <axis>
          <xyz>0 0 -1</xyz>
          <limit>
            <lower>-1e+16</lower>
            <upper>1e+16</upper>
          </limit>
          <dynamics>
            <spring_reference>0</spring_reference>
            <spring_stiffness>0</spring_stiffness>
          </dynamics>
        </axis>
      </joint>
      <link name='down_left_gripper_link_link'>
        <pose relative_to='gripper_base_down_left_gripper_link_joint'>0 0 0 0 -0 0</pose>
        <inertial>
          <pose>0 -0.15 0 0 -0 0</pose>
          <mass>0.001</mass>
          <inertia>
            <ixx>1.3e-06</ixx>
            <ixy>0</ixy>
            <ixz>0</ixz>
            <iyy>4.5e-08</iyy>
            <iyz>0</iyz>
            <izz>1.3e-06</izz>
          </inertia>
        </inertial>
        <collision name='down_left_gripper_link_link_collision'>
          <pose>0 -0.15 0 0 -0 0</pose>
          <geometry>
            <box>
              <size>0.08 0.4 0.04</size>
            </box>
          </geometry>
          <surface>
            <contact>
              <ode/>
            </contact>
            <friction>
              <ode/>
              <torsional>
                <ode/>
              </torsional>
            </friction>
            <bounce/>
          </surface>
          <max_contacts>10</max_contacts>
        </collision>
        <visual name='down_left_gripper_link_link_visual'>
          <pose>0.04 0.04 0 0 -0 3.14</pose>
          <geometry>
            <mesh>
              <scale>0.01 0.01 0.01</scale>
              <uri>model://sort_robotic_arm_description/meshes/Arm_Gripper/Gripper_Link.STL</uri>
            </mesh>
          </geometry>
          <material>
            <script>
              <name>Gazebo/Yellow</name>
              <uri>file://media/materials/scripts/gazebo.material</uri>
            </script>
          </material>
        </visual>
        <self_collide>0</self_collide>
        <enable_wind>0</enable_wind>
        <kinematic>0</kinematic>
      </link>
      <joint name='gripper_base_down_right_gripper_link_joint' type='revolute'>
        <pose relative_to='gripper_base_link'>0.09 -0.58 0.02 0 -0 0</pose>
        <parent>gripper_base_link</parent>
        <child>down_right_gripper_link_link</child>
        <axis>
          <xyz>0 0 1</xyz>
          <limit>
            <lower>-1e+16</lower>
            <upper>1e+16</upper>
          </limit>
          <dynamics>
            <spring_reference>0</spring_reference>
            <spring_stiffness>0</spring_stiffness>
          </dynamics>
        </axis>
      </joint>
      <link name='down_right_gripper_link_link'>
        <pose relative_to='gripper_base_down_right_gripper_link_joint'>0 0 0 0 -0 0</pose>
        <inertial>
          <pose>0 -0.15 0 0 -0 0</pose>
          <mass>0.001</mass>
          <inertia>
            <ixx>1.3e-06</ixx>
            <ixy>0</ixy>
            <ixz>0</ixz>
            <iyy>4.5e-08</iyy>
            <iyz>0</iyz>
            <izz>1.3e-06</izz>
          </inertia>
        </inertial>
        <collision name='down_right_gripper_link_link_collision'>
          <pose>0 -0.15 0 0 -0 0</pose>
          <geometry>
            <box>
              <size>0.08 0.4 0.04</size>
            </box>
          </geometry>
          <surface>
            <contact>
              <ode/>
            </contact>
            <friction>
              <ode/>
              <torsional>
                <ode/>
              </torsional>
            </friction>
            <bounce/>
          </surface>
          <max_contacts>10</max_contacts>
        </collision>
        <visual name='down_right_gripper_link_link_visual'>
          <pose>0.04 0.04 0 0 -0 3.14</pose>
          <geometry>
            <mesh>
              <scale>0.01 0.01 0.01</scale>
              <uri>model://sort_robotic_arm_description/meshes/Arm_Gripper/Gripper_Link.STL</uri>
            </mesh>
          </geometry>
          <material>
            <script>
              <name>Gazebo/Yellow</name>
              <uri>file://media/materials/scripts/gazebo.material</uri>
            </script>
          </material>
        </visual>
        <self_collide>0</self_collide>
        <enable_wind>0</enable_wind>
        <kinematic>0</kinematic>
      </link>
      <joint name='gripper_base_gear1_joint' type='revolute'>
        <pose relative_to='gripper_base_link'>-0.09 -0.36 0.14 0 -0 3.05</pose>
        <parent>gripper_base_link</parent>
        <child>gear1_link</child>
        <axis>
          <xyz>0 0 -1</xyz>
          <limit>
            <lower>-1e+16</lower>
            <upper>1e+16</upper>
          </limit>
          <dynamics>
            <spring_reference>0</spring_reference>
            <spring_stiffness>0</spring_stiffness>
          </dynamics>
        </axis>
      </joint>
      <link name='gear1_link'>
        <pose relative_to='gripper_base_gear1_joint'>0 0 0 0 -0 0</pose>
        <inertial>
          <pose>-0.01 0 0 0 -0 0</pose>
          <mass>0.00332</mass>
          <inertia>
            <ixx>5e-06</ixx>
            <ixy>0</ixy>
            <ixz>0</ixz>
            <iyy>1e-05</iyy>
            <iyz>0</iyz>
            <izz>4.6e-06</izz>
          </inertia>
        </inertial>
        <collision name='gear1_link_collision'>
          <pose>-0.01 0 0 0 -0 0</pose>
          <geometry>
            <cylinder>
              <length>0.04</length>
              <radius>0.133</radius>
            </cylinder>
          </geometry>
          <surface>
            <contact>
              <ode/>
            </contact>
            <friction>
              <ode/>
              <torsional>
                <ode/>
              </torsional>
            </friction>
            <bounce/>
          </surface>
          <max_contacts>10</max_contacts>
        </collision>
        <visual name='gear1_link_visual'>
          <pose>0.1209 -0.1463 0 3.14159 -1.57079 3.14159</pose>
          <geometry>
            <mesh>
              <scale>0.01 0.01 0.01</scale>
              <uri>model://sort_robotic_arm_description/meshes/Arm_Gripper/Gear1.STL</uri>
            </mesh>
          </geometry>
          <material>
            <script>
              <name>Gazebo/Yellow</name>
              <uri>file://media/materials/scripts/gazebo.material</uri>
            </script>
          </material>
        </visual>
        <self_collide>0</self_collide>
        <enable_wind>0</enable_wind>
        <kinematic>0</kinematic>
      </link>
      <joint name='gear1_left_gripper_joint' type='revolute'>
        <pose relative_to='gear1_link'>0 0.3075 0 0 -0 0.45</pose>
        <parent>gear1_link</parent>
        <child>left_gripper_link</child>
        <axis>
          <xyz>0 0 1</xyz>
          <limit>
            <lower>-1e+16</lower>
            <upper>1e+16</upper>
          </limit>
          <dynamics>
            <spring_reference>0</spring_reference>
            <spring_stiffness>0</spring_stiffness>
          </dynamics>
        </axis>
      </joint>
      <link name='left_gripper_link'>
        <pose relative_to='gear1_left_gripper_joint'>0 0 0 0 -0 0</pose>
        <inertial>
          <pose>0 0.28 0 3.14159 0.001593 3.14159</pose>
          <mass>0.00589</mass>
          <inertia>
            <ixx>1.8e-05</ixx>
            <ixy>0</ixy>
            <ixz>0</ixz>
            <iyy>1.6e-06</iyy>
            <iyz>0</iyz>
            <izz>1.9e-05</izz>
          </inertia>
        </inertial>
        <collision name='left_gripper_link_collision'>
          <pose>0.153 -0.05 0 3.14159 0.001593 3.14159</pose>
          <geometry>
            <mesh>
              <scale>0.01 0.01 0.01</scale>
              <uri>model://sort_robotic_arm_description/meshes/Arm_Gripper/Gripper.STL</uri>
            </mesh>
          </geometry>
          <surface>
            <contact>
              <ode/>
            </contact>
            <friction>
              <ode/>
              <torsional>
                <ode/>
              </torsional>
            </friction>
            <bounce/>
          </surface>
          <max_contacts>10</max_contacts>
        </collision>
        <visual name='left_gripper_link_visual'>
          <pose>0.153 -0.05 0 3.14159 0.001593 3.14159</pose>
          <geometry>
            <mesh>
              <scale>0.01 0.01 0.01</scale>
              <uri>model://sort_robotic_arm_description/meshes/Arm_Gripper/Gripper.STL</uri>
            </mesh>
          </geometry>
          <material>
            <script>
              <name>Gazebo/Yellow</name>
              <uri>file://media/materials/scripts/gazebo.material</uri>
            </script>
          </material>
        </visual>
        <self_collide>0</self_collide>
        <enable_wind>0</enable_wind>
        <kinematic>0</kinematic>
      </link>
      <joint name='micro_servo3_gear2_joint' type='revolute'>
        <pose relative_to='gripper_base_link'>0.179 -0.36 0.14 0 -0 0</pose>
        <parent>gripper_base_link</parent>
        <child>gear2_link</child>
        <axis>
          <xyz>0 0 1</xyz>
          <limit>
            <lower>0.1</lower>
            <upper>1.3</upper>
            <effort>10</effort>
            <velocity>1</velocity>
          </limit>
          <dynamics>
            <spring_reference>0</spring_reference>
            <spring_stiffness>0</spring_stiffness>
          </dynamics>
        </axis>
      </joint>
      <link name='gear2_link'>
        <pose relative_to='micro_servo3_gear2_joint'>0 0 0 0 -0 0</pose>
        <inertial>
          <pose>-0.01 0 0 0 -0 0</pose>
          <mass>0.00277</mass>
          <inertia>
            <ixx>5e-06</ixx>
            <ixy>0</ixy>
            <ixz>0</ixz>
            <iyy>1e-05</iyy>
            <iyz>0</iyz>
            <izz>4.6e-06</izz>
          </inertia>
        </inertial>
        <collision name='gear2_link_collision'>
          <pose>-0.01 0 0 0 -0 0</pose>
          <geometry>
            <cylinder>
              <length>0.04</length>
              <radius>0.133</radius>
            </cylinder>
          </geometry>
          <surface>
            <contact>
              <ode/>
            </contact>
            <friction>
              <ode/>
              <torsional>
                <ode/>
              </torsional>
            </friction>
            <bounce/>
          </surface>
          <max_contacts>10</max_contacts>
        </collision>
        <visual name='gear2_link_visual'>
          <pose>0.1209 -0.3475 0 3.14159 -1.57079 3.14159</pose>
          <geometry>
            <mesh>
              <scale>0.01 0.01 0.01</scale>
              <uri>model://sort_robotic_arm_description/meshes/Arm_Gripper/Gear2.STL</uri>
            </mesh>
          </geometry>
          <material>
            <script>
              <name>Gazebo/Yellow</name>
              <uri>file://media/materials/scripts/gazebo.material</uri>
            </script>
          </material>
        </visual>
        <self_collide>0</self_collide>
        <enable_wind>0</enable_wind>
        <kinematic>0</kinematic>
      </link>
      <joint name='gear2_right_gripper_joint' type='revolute'>
        <pose relative_to='gear2_link'>0 -0.3075 0 0 -0 2.78319</pose>
        <parent>gear2_link</parent>
        <child>right_gripper_link</child>
        <axis>
          <xyz>0 0 -1</xyz>
          <limit>
            <lower>-1e+16</lower>
            <upper>1e+16</upper>
          </limit>
          <dynamics>
            <spring_reference>0</spring_reference>
            <spring_stiffness>0</spring_stiffness>
          </dynamics>
        </axis>
      </joint>
      <link name='right_gripper_link'>
        <pose relative_to='gear2_right_gripper_joint'>0 0 0 0 -0 0</pose>
        <inertial>
          <pose>0 0.28 0 0 -0 0</pose>
          <mass>0.00589</mass>
          <inertia>
            <ixx>1.8e-05</ixx>
            <ixy>0</ixy>
            <ixz>0</ixz>
            <iyy>1.6e-06</iyy>
            <iyz>0</iyz>
            <izz>1.9e-05</izz>
          </inertia>
        </inertial>
        <collision name='right_gripper_link_collision'>
          <pose>-0.1462 -0.05 -0.085 0 -0 0</pose>
          <geometry>
            <mesh>
              <scale>0.01 0.01 0.01</scale>
              <uri>model://sort_robotic_arm_description/meshes/Arm_Gripper/Gripper.STL</uri>
            </mesh>
          </geometry>
          <surface>
            <contact>
              <ode/>
            </contact>
            <friction>
              <ode/>
              <torsional>
                <ode/>
              </torsional>
            </friction>
            <bounce/>
          </surface>
          <max_contacts>10</max_contacts>
        </collision>
        <visual name='right_gripper_link_visual'>
          <pose>-0.1462 -0.05 -0.085 0 -0 0</pose>
          <geometry>
            <mesh>
              <scale>0.01 0.01 0.01</scale>
              <uri>model://sort_robotic_arm_description/meshes/Arm_Gripper/Gripper.STL</uri>
            </mesh>
          </geometry>
          <material>
            <script>
              <name>Gazebo/Yellow</name>
              <uri>file://media/materials/scripts/gazebo.material</uri>
            </script>
          </material>
        </visual>
        <self_collide>0</self_collide>
        <enable_wind>0</enable_wind>
        <kinematic>0</kinematic>
      </link>
      <joint name='gripper_base_up_left_gripper_link_joint' type='revolute'>
        <pose relative_to='gripper_base_link'>-0.01 -0.56 0.14 0 0 -0.1</pose>
        <parent>gripper_base_link</parent>
        <child>up_left_gripper_link_link</child>
        <axis>
          <xyz>0 0 -1</xyz>
          <limit>
            <lower>-1e+16</lower>
            <upper>1e+16</upper>
          </limit>
          <dynamics>
            <spring_reference>0</spring_reference>
            <spring_stiffness>0</spring_stiffness>
          </dynamics>
        </axis>
      </joint>
      <link name='up_left_gripper_link_link'>
        <pose relative_to='gripper_base_up_left_gripper_link_joint'>0 0 0 0 -0 0</pose>
        <inertial>
          <pose>0 -0.15 0 0 -0 0</pose>
          <mass>0.001</mass>
          <inertia>
            <ixx>1.3e-06</ixx>
            <ixy>0</ixy>
            <ixz>0</ixz>
            <iyy>4.5e-08</iyy>
            <iyz>0</iyz>
            <izz>1.3e-06</izz>
          </inertia>
        </inertial>
        <collision name='up_left_gripper_link_link_collision'>
          <pose>0 -0.15 0 0 -0 0</pose>
          <geometry>
            <box>
              <size>0.08 0.4 0.04</size>
            </box>
          </geometry>
          <surface>
            <contact>
              <ode/>
            </contact>
            <friction>
              <ode/>
              <torsional>
                <ode/>
              </torsional>
            </friction>
            <bounce/>
          </surface>
          <max_contacts>10</max_contacts>
        </collision>
        <visual name='up_left_gripper_link_link_visual'>
          <pose>0.04 0.04 0 0 -0 3.14</pose>
          <geometry>
            <mesh>
              <scale>0.01 0.01 0.01</scale>
              <uri>model://sort_robotic_arm_description/meshes/Arm_Gripper/Gripper_Link.STL</uri>
            </mesh>
          </geometry>
          <material>
            <script>
              <name>Gazebo/Yellow</name>
              <uri>file://media/materials/scripts/gazebo.material</uri>
            </script>
          </material>
        </visual>
        <self_collide>0</self_collide>
        <enable_wind>0</enable_wind>
        <kinematic>0</kinematic>
      </link>
      <joint name='gripper_base_up_right_gripper_link_joint' type='revolute'>
        <pose relative_to='gripper_base_link'>0.09 -0.56 0.14 0 -0 0</pose>
        <parent>gripper_base_link</parent>
        <child>up_right_gripper_link_link</child>
        <axis>
          <xyz>0 0 1</xyz>
          <limit>
            <lower>-1e+16</lower>
            <upper>1e+16</upper>
          </limit>
          <dynamics>
            <spring_reference>0</spring_reference>
            <spring_stiffness>0</spring_stiffness>
          </dynamics>
        </axis>
      </joint>
      <link name='up_right_gripper_link_link'>
        <pose relative_to='gripper_base_up_right_gripper_link_joint'>0 0 0 0 -0 0</pose>
        <inertial>
          <pose>0 -0.15 0.02 0 -0 0</pose>
          <mass>0.001</mass>
          <inertia>
            <ixx>1.3e-06</ixx>
            <ixy>0</ixy>
            <ixz>0</ixz>
            <iyy>4.5e-08</iyy>
            <iyz>0</iyz>
            <izz>1.3e-06</izz>
          </inertia>
        </inertial>
        <collision name='up_right_gripper_link_link_collision'>
          <pose>0 -0.15 0.02 0 -0 0</pose>
          <geometry>
            <box>
              <size>0.08 0.4 0.04</size>
            </box>
          </geometry>
          <surface>
            <contact>
              <ode/>
            </contact>
            <friction>
              <ode/>
              <torsional>
                <ode/>
              </torsional>
            </friction>
            <bounce/>
          </surface>
          <max_contacts>10</max_contacts>
        </collision>
        <visual name='up_right_gripper_link_link_visual'>
          <pose>0.04 0.04 0 0 -0 3.14</pose>
          <geometry>
            <mesh>
              <scale>0.01 0.01 0.01</scale>
              <uri>model://sort_robotic_arm_description/meshes/Arm_Gripper/Gripper_Link.STL</uri>
            </mesh>
          </geometry>
          <material>
            <script>
              <name>Gazebo/Yellow</name>
              <uri>file://media/materials/scripts/gazebo.material</uri>
            </script>
          </material>
        </visual>
        <self_collide>0</self_collide>
        <enable_wind>0</enable_wind>
        <kinematic>0</kinematic>
      </link>
      <plugin name='gazebo_grasp_fix' filename='libgazebo_grasp_fix.so'>
        <arm>
          <arm_name>gripper_gazebo</arm_name>
          <palm_link>gear2_link</palm_link>
          <palm_link>gear1_link</palm_link>
          <gripper_link>right_gripper_link</gripper_link>
          <gripper_link>left_gripper_link</gripper_link>
        </arm>
        <forces_angle_tolerance>100</forces_angle_tolerance>
        <update_rate>4</update_rate>
        <grip_count_threshold>4</grip_count_threshold>
        <max_grip_count>8</max_grip_count>
        <release_tolerance>0.005</release_tolerance>
        <disable_collisions_on_attach>0</disable_collisions_on_attach>
        <contact_topic>__default_topic__</contact_topic>
      </plugin>
      <static>0</static>
      <plugin name='gazebo_ros2_control' filename='libgazebo_ros2_control.so'>
        <parameters>/home/daniel/ros2_ws/install/sort_robotic_arm_description/share/sort_robotic_arm_description/yaml/config_yaml.yaml</parameters>
      </plugin>
      <pose>0 0 0 0 -0 0</pose>
    </model>
    <state world_name='default'>
      <sim_time>23 842000000</sim_time>
      <real_time>25 745693453</real_time>
      <wall_time>1737156992 778008435</wall_time>
      <iterations>23842</iterations>
      <model name='ground_plane'>
        <pose>0 0 0 0 -0 0</pose>
        <scale>1 1 1</scale>
        <link name='link'>
          <pose>0 0 0 0 -0 0</pose>
          <velocity>0 0 0 0 -0 0</velocity>
          <acceleration>0 0 0 0 -0 0</acceleration>
          <wrench>0 0 0 0 -0 0</wrench>
        </link>
      </model>
      <model name='sort_robotic_arm'>
        <pose>-0.000738 0.011105 0 0 -0 9e-06</pose>
        <scale>1 1 1</scale>
        <link name='arm1_link'>
          <pose>0.085905 -0.116377 0.95277 -1.56987 -0.921719 1.70947</pose>
          <velocity>-0.001278 0.012967 0.008875 0.031593 0.004605 -0.001006</velocity>
          <acceleration>0.307643 -0.542134 -1.73804 -2.97711 -1.52337 -0.441084</acceleration>
          <wrench>0.016093 -0.028359 -0.090917 0 -0 0</wrench>
        </link>
        <link name='arm3_link'>
          <pose>0.151421 -1.42214 0.821882 -1.90085 0.010021 0.162103</pose>
          <velocity>-0.000126 -0.000111 -0.01455 0.007124 0.001863 0.000519</velocity>
          <acceleration>-0.313822 0.456671 -9.97775 -2.30833 1.54147 -0.67324</acceleration>
          <wrench>-0.010497 0.015276 -0.333756 0 -0 0</wrench>
        </link>
        <link name='down_left_gripper_link_link'>
          <pose>0.413371 -1.97415 0.335835 2.92396 0.24119 -2.12874</pose>
          <velocity>-0.000361 0.001824 -0.014443 -0.001649 0.002628 -0.004074</velocity>
          <acceleration>-0.625195 0.372104 -9.5626 3.09843 -0.130575 -3.02897</acceleration>
          <wrench>-0.000625 0.000372 -0.009563 0 -0 0</wrench>
        </link>
        <link name='down_right_gripper_link_link'>
          <pose>0.314662 -1.99014 0.336785 2.9145 -0.23232 2.54696</pose>
          <velocity>-0.000365 0.001775 -0.014435 -0.00171 -0.005293 0.003785</velocity>
          <acceleration>0.357177 0.508843 -9.56255 1.02794 -0.588344 -1.80048</acceleration>
          <wrench>0.000357 0.000509 -0.009563 0 -0 0</wrench>
        </link>
        <link name='gear1_link'>
          <pose>0.452474 -1.71788 0.291188 -2.92195 -0.23937 1.00441</pose>
          <velocity>-0.00052 0.001794 -0.014675 -0.000683 0.001432 -0.002268</velocity>
          <acceleration>-0.434106 0.925797 -9.59507 3.04082 0.414069 0.620683</acceleration>
          <wrench>-0.001441 0.003074 -0.031856 0 -0 0</wrench>
        </link>
        <link name='gear2_link'>
          <pose>0.186947 -1.76089 0.293744 2.9145 -0.232325 2.54696</pose>
          <velocity>-0.000489 0.001638 -0.014564 0.00064 -0.00065 0.002889</velocity>
          <acceleration>-0.364635 0.785884 -9.46537 0.513224 -1.1893 2.88877</acceleration>
          <wrench>-0.00101 0.002177 -0.026219 0 -0 0</wrench>
        </link>
        <link name='gripper_base_link'>
          <pose>0.318482 -1.43884 0.539151 2.81829 -0.0095 -2.981</pose>
          <velocity>-0.000617 0.001974 -0.014948 -0.001103 0.000247 0.000581</velocity>
          <acceleration>-0.332248 0.949449 -9.47542 -1.24796 -0.819826 0.401707</acceleration>
          <wrench>-0.01135 0.032433 -0.32368 0 -0 0</wrench>
        </link>
        <link name='ground_link'>
          <pose>-0.000738 0.011105 0 0 -0 9e-06</pose>
          <velocity>-0 -0 0.004876 -0.000135 9.9e-05 -0</velocity>
          <acceleration>0.432563 -0.427129 10.2541 -0.271768 0.197059 -0.005645</acceleration>
          <wrench>0.210572 -0.207926 4.99169 0 -0 0</wrench>
        </link>
        <link name='left_gripper_link'>
          <pose>0.714246 -1.86551 0.2261 -2.84075 0.120624 -0.181045</pose>
          <velocity>-0.000935 0.001124 -0.014897 -0.000477 -0.000634 0.002952</velocity>
          <acceleration>-0.020611 0.01404 -9.7082 0.95432 0.82684 -1.0778</acceleration>
          <wrench>-0.000121 8.3e-05 -0.057181 0 -0 0</wrench>
        </link>
        <link name='right_gripper_link'>
          <pose>0.005903 -2.00014 0.226371 -2.83435 -0.102717 0.501517</pose>
          <velocity>0.000279 0.001035 -0.014666 -8e-05 0.001836 -0.000902</velocity>
          <acceleration>0.006944 0.008267 -9.73165 -0.004322 -0.197138 -1.03849</acceleration>
          <wrench>4.1e-05 4.9e-05 -0.057319 0 -0 0</wrench>
        </link>
        <link name='servo3_link'>
          <pose>0.219159 -1.06299 1.67813 1.5702 -0.330197 -1.43118</pose>
          <velocity>0.001141 -0.006361 -0.012073 0.007192 0.001206 -0.001005</velocity>
          <acceleration>1.05879 -5.57063 -7.47247 -2.1407 1.23387 2.08273</acceleration>
          <wrench>0.135642 -0.713653 -0.957299 0 -0 0</wrench>
        </link>
        <link name='up_left_gripper_link_link'>
          <pose>0.403235 -1.91796 0.228411 2.92396 0.24119 -2.12874</pose>
          <velocity>-0.000419 0.00169 -0.014472 -0.001892 0.002571 -0.002973</velocity>
          <acceleration>-0.614361 0.357624 -9.57396 -1.30808 0.377149 0.631528</acceleration>
          <wrench>-0.000614 0.000358 -0.009574 0 -0 0</wrench>
        </link>
        <link name='up_right_gripper_link_link'>
          <pose>0.304526 -1.93395 0.229361 2.9145 -0.232323 2.54697</pose>
          <velocity>-0.000394 0.001645 -0.014467 -0.002002 -0.005493 0.002717</velocity>
          <acceleration>0.285612 0.405356 -9.60449 -2.87989 1.07662 -2.24137</acceleration>
          <wrench>0.000286 0.000405 -0.009604 0 -0 0</wrench>
        </link>
        <link name='waist_link'>
          <pose>-0.000738 0.011105 0.56 0 -0 0.139982</pose>
          <velocity>6.6e-05 8.9e-05 0.00488 -0.000135 8.5e-05 -0.000998</velocity>
          <acceleration>0.183848 -0.630656 9.78276 -0.315775 0.428828 -0.977737</acceleration>
          <wrench>0.029539 -0.101327 1.5718 0 -0 0</wrench>
        </link>
      </model>
      <light name='sun'>
        <pose>0 0 10 0 -0 0</pose>
      </light>
    </state>
    <gui fullscreen='0'>
      <camera name='user_camera'>
        <pose>5 -5 2 0 0.275643 2.35619</pose>
        <view_controller>orbit</view_controller>
        <projection_type>perspective</projection_type>
      </camera>
    </gui>
  </world>
</sdf>
