<sdf version='1.7'>
  <world name='default'>
    <light name='sun' type='directional'>
      <cast_shadows>1</cast_shadows>
      <pose>0 0 10 0 -0 0</pose>
      <diffuse>0.8 0.8 0.8 1</diffuse>
      <specular>0.2 0.2 0.2 1</specular>
      <attenuation>
        <range>1000</range>
        <constant>0.9</constant>
        <linear>0.01</linear>
        <quadratic>0.001</quadratic>
      </attenuation>
      <direction>-0.5 0.1 -0.9</direction>
      <spot>
        <inner_angle>0</inner_angle>
        <outer_angle>0</outer_angle>
        <falloff>0</falloff>
      </spot>
    </light>
    <model name='ground_plane'>
      <static>1</static>
      <link name='link'>
        <collision name='collision'>
          <geometry>
            <plane>
              <normal>0 0 1</normal>
              <size>100 100</size>
            </plane>
          </geometry>
          <surface>
            <friction>
              <ode>
                <mu>100</mu>
                <mu2>50</mu2>
              </ode>
              <torsional>
                <ode/>
              </torsional>
            </friction>
            <contact>
              <ode/>
            </contact>
            <bounce/>
          </surface>
          <max_contacts>10</max_contacts>
        </collision>
        <visual name='visual'>
          <cast_shadows>0</cast_shadows>
          <geometry>
            <plane>
              <normal>0 0 1</normal>
              <size>100 100</size>
            </plane>
          </geometry>
          <material>
            <script>
              <uri>file://media/materials/scripts/gazebo.material</uri>
              <name>Gazebo/Grey</name>
            </script>
          </material>
        </visual>
        <self_collide>0</self_collide>
        <enable_wind>0</enable_wind>
        <kinematic>0</kinematic>
      </link>
    </model>
    <gravity>0 0 -9.8</gravity>
    <magnetic_field>6e-06 2.3e-05 -4.2e-05</magnetic_field>
    <atmosphere type='adiabatic'/>
    <physics type='ode'>
      <max_step_size>0.001</max_step_size>
      <real_time_factor>1</real_time_factor>
      <real_time_update_rate>1000</real_time_update_rate>
      <solver>
        <type>quick</type>
        <iters>200</iters>
        <sor>1.3</sor>
      </solver>
      <constraints>
        <cfm>0.0</cfm>
        <erp>0.2</erp>
      </constraints>
    </physics>
    <scene>
      <ambient>0.4 0.4 0.4 1</ambient>
      <background>0.7 0.7 0.7 1</background>
      <shadows>1</shadows>
    </scene>
    <audio>
      <device>default</device>
    </audio>
    <wind/>
    <spherical_coordinates>
      <surface_model>EARTH_WGS84</surface_model>
      <latitude_deg>0</latitude_deg>
      <longitude_deg>0</longitude_deg>
      <elevation>0</elevation>
      <heading_deg>0</heading_deg>
    </spherical_coordinates>
    <state world_name='default'>
      <sim_time>100 740000000</sim_time>
      <real_time>38 464742133</real_time>
      <wall_time>1737797913 709763410</wall_time>
      <iterations>36528</iterations>
      <model name='green_cube_0'>
        <pose>1.09032 -1.763 0.49999 0 -3e-06 4.1e-05</pose>
        <scale>1 1 1</scale>
        <link name='link_0'>
          <pose>1.09032 -1.763 0.49999 0 -3e-06 4.1e-05</pose>
          <velocity>0 0 0 0 -0 0</velocity>
          <acceleration>0 0 -9.8 0 -0 0</acceleration>
          <wrench>0 0 -0.98 0 -0 0</wrench>
        </link>
      </model>
      <model name='ground_plane'>
        <pose>0 0 0 0 -0 0</pose>
        <scale>1 1 1</scale>
        <link name='link'>
          <pose>0 0 0 0 -0 0</pose>
          <velocity>0 0 0 0 -0 0</velocity>
          <acceleration>0 0 0 0 -0 0</acceleration>
          <wrench>0 0 0 0 -0 0</wrench>
        </link>
      </model>
      <model name='measure_cube'>
        <pose>0.046434 -1.33265 0.5 0 -0 0</pose>
        <scale>1 1 1</scale>
        <link name='link_0'>
          <pose>0.046434 -1.33265 0.5 0 -0 0</pose>
          <velocity>0 0 0 0 -0 0</velocity>
          <acceleration>0 0 0 0 -0 0</acceleration>
          <wrench>0 0 0 0 -0 0</wrench>
        </link>
      </model>
      <model name='red_ball'>
        <pose>-1.7482 -1.84378 0.5 0 -0 0</pose>
        <scale>1 1 1</scale>
        <link name='link_0'>
          <pose>-1.7482 -1.84378 0.5 0 -0 0</pose>
          <velocity>0 0 0 0 -0 0</velocity>
          <acceleration>0 0 0 0 -0 0</acceleration>
          <wrench>0 0 0 0 -0 0</wrench>
        </link>
      </model>
      <model name='sort_robotic_arm'>
        <pose>0.001181 0.025712 0 -0 -0 -0.000258</pose>
        <scale>1 1 1</scale>
        <link name='arm1_link'>
          <pose>0.069138 -0.112545 0.952788 -1.57 -0.788459 1.56936</pose>
          <velocity>-9.8e-05 0.018998 0.010476 0.03736 -9.5e-05 2.4e-05</velocity>
          <acceleration>-0.423093 -0.261086 0.065611 -2.68671 -0.168766 3.12823</acceleration>
          <wrench>-0.022132 -0.013657 0.003432 0 -0 0</wrench>
        </link>
        <link name='arm3_link'>
          <pose>-0.047789 -1.58042 2.48621 1.57368 0.785487 -1.56929</pose>
          <velocity>-0.000109 -0.003089 -0.009901 -0.00276 -0.001106 0.00109</velocity>
          <acceleration>-0.587682 -5.20285 -4.39709 0.496722 -1.00347 -0.263544</acceleration>
          <wrench>-0.019658 -0.174035 -0.147083 0 -0 0</wrench>
        </link>
        <link name='down_left_gripper_link_link'>
          <pose>-0.118258 -2.31233 2.97036 1.58924 -1.45763 -1.58745</pose>
          <velocity>0.000242 -0.002354 -0.008853 0.03942 0.00052 0.001337</velocity>
          <acceleration>-0.087747 -4.3376 -9.9454 -1.00852 0.665143 -1.51054</acceleration>
          <wrench>-8.8e-05 -0.004338 -0.009945 0 -0 0</wrench>
        </link>
        <link name='down_right_gripper_link_link'>
          <pose>-0.118524 -2.24163 3.04108 -1.57288 0.009635 1.57245</pose>
          <velocity>0.000207 -0.002269 -0.008934 -0.032007 -0.001162 0.001044</velocity>
          <acceleration>-0.531095 -0.21999 -4.10573 -0.240418 0.256094 0.999463</acceleration>
          <wrench>-0.000531 -0.00022 -0.004106 0 -0 0</wrench>
        </link>
        <link name='gear1_link'>
          <pose>-0.237982 -2.21352 2.75799 -1.59187 1.47179 1.5515</pose>
          <velocity>0.000473 -0.002767 -0.009084 0.021966 -0.001027 0.000991</velocity>
          <acceleration>-0.028883 -5.56165 -4.23962 -0.805683 -1.22609 1.04368</acceleration>
          <wrench>-9.6e-05 -0.018465 -0.014076 0 -0 0</wrench>
        </link>
        <link name='gear2_link'>
          <pose>-0.238697 -2.02332 2.94822 -1.57288 0.006418 1.57246</pose>
          <velocity>3.7e-05 -0.002561 -0.009305 -0.022358 -0.001011 0.001387</velocity>
          <acceleration>-0.473857 -5.21074 -4.13982 -1.85695 -0.780156 -2.51636</acceleration>
          <wrench>-0.001313 -0.014434 -0.011467 0 -0 0</wrench>
        </link>
        <link name='gripper_base_link'>
          <pose>-0.098119 -1.89506 2.56739 -1.57374 -0.785495 1.57456</pose>
          <velocity>0.000186 -0.00286 -0.009319 -0.001316 -0.00093 0.001575</velocity>
          <acceleration>-0.449149 -5.05513 -4.19067 -0.858339 -0.343878 0.349026</acceleration>
          <wrench>-0.015343 -0.172683 -0.143153 0 -0 0</wrench>
        </link>
        <link name='ground_link'>
          <pose>0.001181 0.025712 0 -0 -0 -0.000258</pose>
          <velocity>0 -0 0.005839 0.000417 -0.000166 0</velocity>
          <acceleration>-0.634805 -2.9171 10.1279 0.833394 -0.331617 0.014055</acceleration>
          <wrench>-0.309023 -1.42004 4.93028 0 -0 0</wrench>
        </link>
        <link name='left_gripper_link'>
          <pose>-0.237405 -2.51951 2.7276 1.57308 0.421968 -1.56818</pose>
          <velocity>0.000747 -0.002089 -0.015794 -0.016731 -0.001507 0.001306</velocity>
          <acceleration>-0.009769 -0.482243 -9.1848 -2.90578 0.452375 1.4874</acceleration>
          <wrench>-5.8e-05 -0.00284 -0.054098 0 -0 0</wrench>
        </link>
        <link name='right_gripper_link'>
          <pose>-0.23934 -2.02135 3.25571 1.57588 1.15049 -1.56448</pose>
          <velocity>-0.000287 0.004319 -0.009341 0.018671 -0.001092 0.001508</velocity>
          <acceleration>-0.61758 -0.640996 -9.27436 -0.761045 -1.04419 -1.45407</acceleration>
          <wrench>-0.003638 -0.003775 -0.054626 0 -0 0</wrench>
        </link>
        <link name='servo3_link'>
          <pose>0.068872 -0.963574 1.79874 -1.57 -0.785493 1.56936</pose>
          <velocity>-0.000129 -0.004655 -0.011159 -0.00239 -4e-06 1e-06</velocity>
          <acceleration>-0.500153 -6.55317 -5.47941 -2.02382 -0.159944 -0.058648</acceleration>
          <wrench>-0.064075 -0.839527 -0.701967 0 -0 0</wrench>
        </link>
        <link name='up_left_gripper_link_link'>
          <pose>-0.238251 -2.29839 2.95597 1.58929 -1.45793 -1.5875</pose>
          <velocity>0.000381 -0.002563 -0.008949 0.038866 0.00072 0.001824</velocity>
          <acceleration>0.123488 -4.55334 -9.97297 -1.5659 -1.06967 -0.827852</acceleration>
          <wrench>0.000123 -0.004553 -0.009973 0 -0 0</wrench>
        </link>
        <link name='up_right_gripper_link_link'>
          <pose>-0.238517 -2.22769 3.02669 -1.57288 0.009882 1.57246</pose>
          <velocity>0.00035 -0.002476 -0.00903 -0.033491 -0.001002 0.00155</velocity>
          <acceleration>-0.362625 -0.232504 -4.24131 -1.75418 0.409398 3.11051</acceleration>
          <wrench>-0.000363 -0.000233 -0.004241 0 -0 0</wrench>
        </link>
        <link name='waist_link'>
          <pose>0.001181 0.025713 0.56 -0 -0 -0.00031</pose>
          <velocity>-6.2e-05 -0.000214 0.005844 0.000416 -0.000196 2.3e-05</velocity>
          <acceleration>-0.272571 -1.99556 11.6174 0.832429 -0.36013 0.03705</acceleration>
          <wrench>-0.043794 -0.320627 1.86657 0 -0 0</wrench>
        </link>
      </model>
      <light name='sun'>
        <pose>0 0 10 0 -0 0</pose>
      </light>
    </state>
    <gui fullscreen='0'>
      <camera name='user_camera'>
        <pose>8.15403 -2.07917 2.12372 0 0.236932 2.85143</pose>
        <view_controller>orbit</view_controller>
        <projection_type>perspective</projection_type>
      </camera>
    </gui>
    <model name='sort_robotic_arm'>
      <link name='ground_link'>
        <inertial>
          <pose>0.011375 -1.86413 1.79743 0 -0 0</pose>
          <mass>0.4868</mass>
          <inertia>
            <ixx>2.29682</ixx>
            <ixy>-0.0101959</ixy>
            <ixz>0.00793771</ixz>
            <iyy>2.33883</iyy>
            <iyz>0.823136</iyz>
            <izz>2.36484</izz>
          </inertia>
        </inertial>
        <collision name='ground_link_fixed_joint_lump__base_link_collision'>
          <pose>0 0 0.28 0 -0 0</pose>
          <geometry>
            <cylinder>
              <length>0.56</length>
              <radius>0.60625</radius>
            </cylinder>
          </geometry>
          <surface>
            <contact>
              <ode/>
            </contact>
            <friction>
              <ode/>
              <torsional>
                <ode/>
              </torsional>
            </friction>
            <bounce/>
          </surface>
          <max_contacts>10</max_contacts>
        </collision>
        <collision name='ground_link_fixed_joint_lump__servo1_link_collision_1'>
          <pose>0.087 -0.0229 0.364 0 -0 0</pose>
          <geometry>
            <box>
              <size>0.558 0.205 0.474</size>
            </box>
          </geometry>
          <surface>
            <contact>
              <ode/>
            </contact>
            <friction>
              <ode/>
              <torsional>
                <ode/>
              </torsional>
            </friction>
            <bounce/>
          </surface>
          <max_contacts>10</max_contacts>
        </collision>
        <collision name='ground_link_fixed_joint_lump__left_tower_link_collision_2'>
          <pose>2 -3 2 3.14159 1.57079 3.14159</pose>
          <geometry>
            <box>
              <size>4 0.2 0.2</size>
            </box>
          </geometry>
          <surface>
            <contact>
              <ode/>
            </contact>
            <friction>
              <ode/>
              <torsional>
                <ode/>
              </torsional>
            </friction>
            <bounce/>
          </surface>
          <max_contacts>10</max_contacts>
        </collision>
        <collision name='ground_link_fixed_joint_lump__right_tower_link_collision_3'>
          <pose>-2 -3 2 3.14159 1.57079 3.14159</pose>
          <geometry>
            <box>
              <size>4 0.2 0.2</size>
            </box>
          </geometry>
          <surface>
            <contact>
              <ode/>
            </contact>
            <friction>
              <ode/>
              <torsional>
                <ode/>
              </torsional>
            </friction>
            <bounce/>
          </surface>
          <max_contacts>10</max_contacts>
        </collision>
        <collision name='ground_link_fixed_joint_lump__up_tower_link_collision_4'>
          <pose>0 -3 4.1 0 -0 0</pose>
          <geometry>
            <box>
              <size>4 0.2 0.2</size>
            </box>
          </geometry>
          <surface>
            <contact>
              <ode/>
            </contact>
            <friction>
              <ode/>
              <torsional>
                <ode/>
              </torsional>
            </friction>
            <bounce/>
          </surface>
          <max_contacts>10</max_contacts>
        </collision>
        <collision name='ground_link_fixed_joint_lump__camera_link_collision_5'>
          <pose>0 -3 3.95 1.57159 1.57079 3.14159</pose>
          <geometry>
            <box>
              <size>0.1 0.1 0.2</size>
            </box>
          </geometry>
          <surface>
            <contact>
              <ode/>
            </contact>
            <friction>
              <ode/>
              <torsional>
                <ode/>
              </torsional>
            </friction>
            <bounce/>
          </surface>
          <max_contacts>10</max_contacts>
        </collision>
        <visual name='ground_link_fixed_joint_lump__base_link_visual'>
          <pose>-0.60625 0.60625 0 1.57 -0 0</pose>
          <geometry>
            <mesh>
              <scale>0.01 0.01 0.01</scale>
              <uri>model://sort_robotic_arm_description/meshes/Arm_Base/Base.STL</uri>
            </mesh>
          </geometry>
          <material>
            <script>
              <name>Gazebo/Yellow</name>
              <uri>file://media/materials/scripts/gazebo.material</uri>
            </script>
          </material>
        </visual>
        <visual name='ground_link_fixed_joint_lump__servo1_link_visual_1'>
          <pose>0.1025 0.1825 0.12 0 -0 3.14</pose>
          <geometry>
            <mesh>
              <scale>0.01 0.01 0.01</scale>
              <uri>model://sort_robotic_arm_description/meshes/Servos/Servo_MG996R.STL</uri>
            </mesh>
          </geometry>
          <material>
            <script>
              <name>Gazebo/Gray</name>
              <uri>file://media/materials/scripts/gazebo.material</uri>
            </script>
          </material>
        </visual>
        <visual name='ground_link_fixed_joint_lump__left_tower_link_visual_2'>
          <pose>2 -3 2 3.14159 1.57079 3.14159</pose>
          <geometry>
            <box>
              <size>4 0.2 0.2</size>
            </box>
          </geometry>
          <material>
            <script>
              <name>Gazebo/Blue</name>
              <uri>file://media/materials/scripts/gazebo.material</uri>
            </script>
          </material>
        </visual>
        <visual name='ground_link_fixed_joint_lump__right_tower_link_visual_3'>
          <pose>-2 -3 2 3.14159 1.57079 3.14159</pose>
          <geometry>
            <box>
              <size>4 0.2 0.2</size>
            </box>
          </geometry>
          <material>
            <script>
              <name>Gazebo/Blue</name>
              <uri>file://media/materials/scripts/gazebo.material</uri>
            </script>
          </material>
        </visual>
        <visual name='ground_link_fixed_joint_lump__up_tower_link_visual_4'>
          <pose>0 -3 4.1 0 -0 0</pose>
          <geometry>
            <box>
              <size>4 0.2 0.2</size>
            </box>
          </geometry>
          <material>
            <script>
              <name>Gazebo/Blue</name>
              <uri>file://media/materials/scripts/gazebo.material</uri>
            </script>
          </material>
        </visual>
        <visual name='ground_link_fixed_joint_lump__camera_link_visual_5'>
          <pose>0 -3 3.95 1.57159 1.57079 3.14159</pose>
          <geometry>
            <box>
              <size>0.1 0.1 0.2</size>
            </box>
          </geometry>
          <material>
            <script>
              <name>Gazebo/Red</name>
              <uri>file://media/materials/scripts/gazebo.material</uri>
            </script>
          </material>
        </visual>
        <sensor name='camera' type='camera'>
          <visualize>1</visualize>
          <update_rate>5</update_rate>
          <camera>
            <horizontal_fov>1.0856</horizontal_fov>
            <image>
              <width>640</width>
              <height>480</height>
              <format>R8G8B8</format>
            </image>
            <clip>
              <near>0.1</near>
              <far>10</far>
            </clip>
          </camera>
          <plugin name='camera_controller' filename='libgazebo_ros_camera.so'>
            <frame_name>camera_optical_frame</frame_name>
          </plugin>
          <pose>0 -3 3.95 3.14159 1.57079 -1.57159</pose>
        </sensor>
        <self_collide>0</self_collide>
        <enable_wind>0</enable_wind>
        <kinematic>0</kinematic>
      </link>
      <joint name='servo1_waist_joint' type='revolute'>
        <pose relative_to='ground_link'>0 0 0.56 0 -0 0</pose>
        <parent>ground_link</parent>
        <child>waist_link</child>
        <axis>
          <xyz>0 0 1</xyz>
          <limit>
            <lower>-1e+16</lower>
            <upper>1e+16</upper>
          </limit>
          <dynamics>
            <spring_reference>0</spring_reference>
            <spring_stiffness>0</spring_stiffness>
          </dynamics>
        </axis>
      </joint>
      <link name='waist_link'>
        <pose relative_to='servo1_waist_joint'>0 0 0 0 -0 0</pose>
        <inertial>
          <pose>-0.085569 -0.042339 0.150536 0 -0 0</pose>
          <mass>0.16067</mass>
          <inertia>
            <ixx>0.104657</ixx>
            <ixy>-0.000887275</ixy>
            <ixz>-0.00152183</ixz>
            <iyy>0.0136117</iyy>
            <iyz>-0.00726861</iyz>
            <izz>0.0822322</izz>
          </inertia>
        </inertial>
        <collision name='waist_link_collision'>
          <pose>0 0 0.08 0 -0 0</pose>
          <geometry>
            <cylinder>
              <length>0.16</length>
              <radius>0.485</radius>
            </cylinder>
          </geometry>
          <surface>
            <contact>
              <ode/>
            </contact>
            <friction>
              <ode/>
              <torsional>
                <ode/>
              </torsional>
            </friction>
            <bounce/>
          </surface>
          <max_contacts>10</max_contacts>
        </collision>
        <collision name='waist_link_fixed_joint_lump__servo2_link_collision_1'>
          <pose>-0.216 -0.106876 0.258051 0.785 -0 0</pose>
          <geometry>
            <box>
              <size>0.558 0.205 0.474</size>
            </box>
          </geometry>
          <surface>
            <contact>
              <ode/>
            </contact>
            <friction>
              <ode/>
              <torsional>
                <ode/>
              </torsional>
            </friction>
            <bounce/>
          </surface>
          <max_contacts>10</max_contacts>
        </collision>
        <visual name='waist_link_visual'>
          <pose>-0.485 -0.485 0 0 -0 0</pose>
          <geometry>
            <mesh>
              <scale>0.01 0.01 0.01</scale>
              <uri>model://sort_robotic_arm_description/meshes/Arm_Base/Waist.STL</uri>
            </mesh>
          </geometry>
          <material>
            <script>
              <name>Gazebo/Yellow</name>
              <uri>file://media/materials/scripts/gazebo.material</uri>
            </script>
          </material>
        </visual>
        <visual name='waist_link_fixed_joint_lump__servo2_link_visual_1'>
          <pose>-0.41 -0.186347 0.593754 -1.57 0.785796 -1.56967</pose>
          <geometry>
            <mesh>
              <scale>0.01 0.01 0.01</scale>
              <uri>model://sort_robotic_arm_description/meshes/Servos/Servo_MG996R.STL</uri>
            </mesh>
          </geometry>
          <material>
            <script>
              <name>Gazebo/Gray</name>
              <uri>file://media/materials/scripts/gazebo.material</uri>
            </script>
          </material>
        </visual>
        <self_collide>0</self_collide>
        <enable_wind>0</enable_wind>
        <kinematic>0</kinematic>
      </link>
      <joint name='servo2_arm1_joint' type='revolute'>
        <pose relative_to='waist_link'>0.068 -0.138396 0.392743 -1.57 -0.785796 1.56967</pose>
        <parent>waist_link</parent>
        <child>arm1_link</child>
        <axis>
          <xyz>0 0 1</xyz>
          <limit>
            <lower>-1e+16</lower>
            <upper>1e+16</upper>
          </limit>
          <dynamics>
            <spring_reference>0</spring_reference>
            <spring_stiffness>0</spring_stiffness>
          </dynamics>
        </axis>
      </joint>
      <link name='arm1_link'>
        <pose relative_to='servo2_arm1_joint'>0 0 0 0 -0 0</pose>
        <inertial>
          <pose>0.025 -0.63 -0.05 1.57 -0 0</pose>
          <mass>0.05231</mass>
          <inertia>
            <ixx>0.01</ixx>
            <ixy>0</ixy>
            <ixz>0</ixz>
            <iyy>6e-05</iyy>
            <iyz>0</iyz>
            <izz>0.01</izz>
          </inertia>
        </inertial>
        <collision name='arm1_link_collision'>
          <pose>0.025 -0.63 -0.05 1.57 -0 0</pose>
          <geometry>
            <cylinder>
              <length>1.62</length>
              <radius>0.21</radius>
            </cylinder>
          </geometry>
          <surface>
            <contact>
              <ode/>
            </contact>
            <friction>
              <ode/>
              <torsional>
                <ode/>
              </torsional>
            </friction>
            <bounce/>
          </surface>
          <max_contacts>10</max_contacts>
        </collision>
        <visual name='arm1_link_visual'>
          <pose>0.3125 0.21 -0.23 0 0 -3.14</pose>
          <geometry>
            <mesh>
              <scale>0.01 0.01 0.01</scale>
              <uri>model://sort_robotic_arm_description/meshes/Arm_Base/Arm1.STL</uri>
            </mesh>
          </geometry>
          <material>
            <script>
              <name>Gazebo/Yellow</name>
              <uri>file://media/materials/scripts/gazebo.material</uri>
            </script>
          </material>
        </visual>
        <self_collide>0</self_collide>
        <enable_wind>0</enable_wind>
        <kinematic>0</kinematic>
      </link>
      <joint name='arm1_servo3_joint' type='revolute'>
        <pose relative_to='arm1_link'>0 -1.2 0 0 -0 0</pose>
        <parent>arm1_link</parent>
        <child>servo3_link</child>
        <axis>
          <xyz>0 0 1</xyz>
          <limit>
            <lower>-1e+16</lower>
            <upper>1e+16</upper>
          </limit>
          <dynamics>
            <spring_reference>0</spring_reference>
            <spring_stiffness>0</spring_stiffness>
          </dynamics>
        </axis>
      </joint>
      <link name='servo3_link'>
        <pose relative_to='arm1_servo3_joint'>0 0 0 0 -0 0</pose>
        <inertial>
          <pose>-0 -0.195596 0.182399 0 -0 1.57</pose>
          <mass>0.12811</mass>
          <inertia>
            <ixx>0.0184931</ixx>
            <ixy>-2.10122e-06</ixy>
            <ixz>-0.000549903</ixz>
            <iyy>0.0131317</iyy>
            <iyz>-4.37902e-07</iyz>
            <izz>0.0127816</izz>
          </inertia>
        </inertial>
        <collision name='servo3_link_collision'>
          <pose>0 -0.1 0.237 0 -0 1.57</pose>
          <geometry>
            <box>
              <size>0.558 0.205 0.474</size>
            </box>
          </geometry>
          <surface>
            <contact>
              <ode/>
            </contact>
            <friction>
              <ode/>
              <torsional>
                <ode/>
              </torsional>
            </friction>
            <bounce/>
          </surface>
          <max_contacts>10</max_contacts>
        </collision>
        <collision name='servo3_link_fixed_joint_lump__arm2_link_collision_1'>
          <pose>0 -0.349785 0.135557 3.14 -0 0</pose>
          <geometry>
            <box>
              <size>0.38 1.15 0.27</size>
            </box>
          </geometry>
          <surface>
            <contact>
              <ode/>
            </contact>
            <friction>
              <ode/>
              <torsional>
                <ode/>
              </torsional>
            </friction>
            <bounce/>
          </surface>
          <max_contacts>10</max_contacts>
        </collision>
        <collision name='servo3_link_fixed_joint_lump__micro_servo1_link_collision_2'>
          <pose>-8e-05 -0.049841 0.100079 1.57159 -0.000796 -1.5708</pose>
          <geometry>
            <box>
              <size>0.326 0.124 0.299</size>
            </box>
          </geometry>
          <surface>
            <contact>
              <ode/>
            </contact>
            <friction>
              <ode/>
              <torsional>
                <ode/>
              </torsional>
            </friction>
            <bounce/>
          </surface>
          <max_contacts>10</max_contacts>
        </collision>
        <visual name='servo3_link_visual'>
          <pose>-0.1025 0.1825 0.474 3.14 -0 0</pose>
          <geometry>
            <mesh>
              <scale>0.01 0.01 0.01</scale>
              <uri>model://sort_robotic_arm_description/meshes/Servos/Servo_MG996R.STL</uri>
            </mesh>
          </geometry>
          <material>
            <script>
              <name>Gazebo/Gray</name>
              <uri>file://media/materials/scripts/gazebo.material</uri>
            </script>
          </material>
        </visual>
        <visual name='servo3_link_fixed_joint_lump__arm2_link_visual_1'>
          <pose>-0.19 0.252885 0.241598 3.14 -0 0</pose>
          <geometry>
            <mesh>
              <scale>0.01 0.01 0.01</scale>
              <uri>model://sort_robotic_arm_description/meshes/Arm_Base/Arm2.STL</uri>
            </mesh>
          </geometry>
          <material>
            <script>
              <name>Gazebo/Yellow</name>
              <uri>file://media/materials/scripts/gazebo.material</uri>
            </script>
          </material>
        </visual>
        <visual name='servo3_link_fixed_joint_lump__micro_servo1_link_visual_2'>
          <pose>0.119908 -0.664316 0.116154 -1.5692 1.57079 -3.14159</pose>
          <geometry>
            <mesh>
              <scale>0.01 0.01 0.01</scale>
              <uri>model://sort_robotic_arm_description/meshes/Servos/Micro_Servo.STL</uri>
            </mesh>
          </geometry>
          <material>
            <script>
              <name>Gazebo/Blue</name>
              <uri>file://media/materials/scripts/gazebo.material</uri>
            </script>
          </material>
        </visual>
        <self_collide>0</self_collide>
        <enable_wind>0</enable_wind>
        <kinematic>0</kinematic>
      </link>
      <joint name='micro_servo1_arm3_joint' type='revolute'>
        <pose relative_to='servo3_link'>0.049908 -0.922316 0.116509 0.001593 0.001593 -3.14159</pose>
        <parent>servo3_link</parent>
        <child>arm3_link</child>
        <axis>
          <xyz>0 1 0</xyz>
          <limit>
            <lower>-1e+16</lower>
            <upper>1e+16</upper>
          </limit>
          <dynamics>
            <spring_reference>0</spring_reference>
            <spring_stiffness>0</spring_stiffness>
          </dynamics>
        </axis>
      </joint>
      <link name='arm3_link'>
        <pose relative_to='micro_servo1_arm3_joint'>0 0 0 0 -0 0</pose>
        <inertial>
          <pose>0 0.206915 0 -1.57 0 0</pose>
          <mass>0.03345</mass>
          <inertia>
            <ixx>0.000145564</ixx>
            <ixy>-4.24871e-11</ixy>
            <ixz>6.94665e-06</ixz>
            <iyy>0.000132564</iyy>
            <iyz>-5.53956e-08</iyz>
            <izz>4.50001e-05</izz>
          </inertia>
        </inertial>
        <collision name='arm3_link_collision'>
          <pose>0 0.2 0 -1.57 0 0</pose>
          <geometry>
            <box>
              <size>0.28 0.33 0.46</size>
            </box>
          </geometry>
          <surface>
            <contact>
              <ode/>
            </contact>
            <friction>
              <ode/>
              <torsional>
                <ode/>
              </torsional>
            </friction>
            <bounce/>
          </surface>
          <max_contacts>10</max_contacts>
        </collision>
        <collision name='arm3_link_fixed_joint_lump__micro_servo2_link_collision_1'>
          <pose>0 0.218 0 1.57 -0 1.57</pose>
          <geometry>
            <box>
              <size>0.326 0.124 0.299</size>
            </box>
          </geometry>
          <surface>
            <contact>
              <ode/>
            </contact>
            <friction>
              <ode/>
              <torsional>
                <ode/>
              </torsional>
            </friction>
            <bounce/>
          </surface>
          <max_contacts>10</max_contacts>
        </collision>
        <visual name='arm3_link_visual'>
          <pose>-0.14 0 0.215 -1.57 0 0</pose>
          <geometry>
            <mesh>
              <scale>0.01 0.01 0.01</scale>
              <uri>model://sort_robotic_arm_description/meshes/Arm_Base/Arm3.STL</uri>
            </mesh>
          </geometry>
          <material>
            <script>
              <name>Gazebo/Yellow</name>
              <uri>file://media/materials/scripts/gazebo.material</uri>
            </script>
          </material>
        </visual>
        <visual name='arm3_link_fixed_joint_lump__micro_servo2_link_visual_1'>
          <pose>-0.098 0.34 0.055 3.14159 1.57079 3.14159</pose>
          <geometry>
            <mesh>
              <scale>0.01 0.01 0.01</scale>
              <uri>model://sort_robotic_arm_description/meshes/Servos/Micro_Servo.STL</uri>
            </mesh>
          </geometry>
          <material>
            <script>
              <name>Gazebo/Blue</name>
              <uri>file://media/materials/scripts/gazebo.material</uri>
            </script>
          </material>
        </visual>
        <self_collide>0</self_collide>
        <enable_wind>0</enable_wind>
        <kinematic>0</kinematic>
      </link>
      <joint name='micro_servo2_gripper_base_joint' type='revolute'>
        <pose relative_to='arm3_link'>0.165 0.28 0.05 0.001593 -0.001593 3.14159</pose>
        <parent>arm3_link</parent>
        <child>gripper_base_link</child>
        <axis>
          <xyz>1 0 0</xyz>
          <limit>
            <lower>-1e+16</lower>
            <upper>1e+16</upper>
          </limit>
          <dynamics>
            <spring_reference>0</spring_reference>
            <spring_stiffness>0</spring_stiffness>
          </dynamics>
        </axis>
      </joint>
      <link name='gripper_base_link'>
        <pose relative_to='micro_servo2_gripper_base_joint'>0 0 0 0 -0 0</pose>
        <inertial>
          <pose>0.148902 -0.317617 0 0 -0 0</pose>
          <mass>0.03416</mass>
          <inertia>
            <ixx>0.000183162</ixx>
            <ixy>0.000129211</ixy>
            <ixz>5.5e-06</ixz>
            <iyy>0.000265474</iyy>
            <iyz>1.6e-05</iyz>
            <izz>0.000415636</izz>
          </inertia>
        </inertial>
        <collision name='gripper_base_link_collision'>
          <pose>0.1 -0.28 0 0 -0 0</pose>
          <geometry>
            <box>
              <size>0.533 0.77 0.24</size>
            </box>
          </geometry>
          <surface>
            <contact>
              <ode/>
            </contact>
            <friction>
              <ode/>
              <torsional>
                <ode/>
              </torsional>
            </friction>
            <bounce/>
          </surface>
          <max_contacts>10</max_contacts>
        </collision>
        <collision name='gripper_base_link_fixed_joint_lump__micro_servo3_link_collision_1'>
          <pose>0.23 -0.38 0 0 -0 0</pose>
          <geometry>
            <box>
              <size>0.326 0.124 0.299</size>
            </box>
          </geometry>
          <surface>
            <contact>
              <ode/>
            </contact>
            <friction>
              <ode/>
              <torsional>
                <ode/>
              </torsional>
            </friction>
            <bounce/>
          </surface>
          <max_contacts>10</max_contacts>
        </collision>
        <visual name='gripper_base_link_visual'>
          <pose>-0.14 -0.63 -0.14 0 -0 0</pose>
          <geometry>
            <mesh>
              <scale>0.01 0.01 0.01</scale>
              <uri>model://sort_robotic_arm_description/meshes/Arm_Gripper/Gripper_Base.STL</uri>
            </mesh>
          </geometry>
          <material>
            <script>
              <name>Gazebo/Yellow</name>
              <uri>file://media/materials/scripts/gazebo.material</uri>
            </script>
          </material>
        </visual>
        <visual name='gripper_base_link_fixed_joint_lump__micro_servo3_link_visual_1'>
          <pose>0.117 -0.38 -0.1037 0 -0 1.57</pose>
          <geometry>
            <mesh>
              <scale>0.01 0.01 0.01</scale>
              <uri>model://sort_robotic_arm_description/meshes/Servos/Micro_Servo.STL</uri>
            </mesh>
          </geometry>
          <material>
            <script>
              <name>Gazebo/Blue</name>
              <uri>file://media/materials/scripts/gazebo.material</uri>
            </script>
          </material>
        </visual>
        <self_collide>0</self_collide>
        <enable_wind>0</enable_wind>
        <kinematic>0</kinematic>
      </link>
      <joint name='gripper_base_down_left_gripper_link_joint' type='revolute'>
        <pose relative_to='gripper_base_link'>-0.01 -0.58 0.02 0 0 -0.1</pose>
        <parent>gripper_base_link</parent>
        <child>down_left_gripper_link_link</child>
        <axis>
          <xyz>0 0 -1</xyz>
          <limit>
            <lower>-1e+16</lower>
            <upper>1e+16</upper>
          </limit>
          <dynamics>
            <spring_reference>0</spring_reference>
            <spring_stiffness>0</spring_stiffness>
          </dynamics>
        </axis>
      </joint>
      <link name='down_left_gripper_link_link'>
        <pose relative_to='gripper_base_down_left_gripper_link_joint'>0 0 0 0 -0 0</pose>
        <inertial>
          <pose>0 -0.15 0 0 -0 0</pose>
          <mass>0.001</mass>
          <inertia>
            <ixx>1.3e-06</ixx>
            <ixy>0</ixy>
            <ixz>0</ixz>
            <iyy>4.5e-08</iyy>
            <iyz>0</iyz>
            <izz>1.3e-06</izz>
          </inertia>
        </inertial>
        <collision name='down_left_gripper_link_link_collision'>
          <pose>0 -0.15 0 0 -0 0</pose>
          <geometry>
            <box>
              <size>0.08 0.4 0.04</size>
            </box>
          </geometry>
          <surface>
            <contact>
              <ode/>
            </contact>
            <friction>
              <ode/>
              <torsional>
                <ode/>
              </torsional>
            </friction>
            <bounce/>
          </surface>
          <max_contacts>10</max_contacts>
        </collision>
        <visual name='down_left_gripper_link_link_visual'>
          <pose>0.04 0.04 0 0 -0 3.14</pose>
          <geometry>
            <mesh>
              <scale>0.01 0.01 0.01</scale>
              <uri>model://sort_robotic_arm_description/meshes/Arm_Gripper/Gripper_Link.STL</uri>
            </mesh>
          </geometry>
          <material>
            <script>
              <name>Gazebo/Yellow</name>
              <uri>file://media/materials/scripts/gazebo.material</uri>
            </script>
          </material>
        </visual>
        <self_collide>0</self_collide>
        <enable_wind>0</enable_wind>
        <kinematic>0</kinematic>
      </link>
      <joint name='gripper_base_down_right_gripper_link_joint' type='revolute'>
        <pose relative_to='gripper_base_link'>0.09 -0.58 0.02 0 -0 0</pose>
        <parent>gripper_base_link</parent>
        <child>down_right_gripper_link_link</child>
        <axis>
          <xyz>0 0 1</xyz>
          <limit>
            <lower>-1e+16</lower>
            <upper>1e+16</upper>
          </limit>
          <dynamics>
            <spring_reference>0</spring_reference>
            <spring_stiffness>0</spring_stiffness>
          </dynamics>
        </axis>
      </joint>
      <link name='down_right_gripper_link_link'>
        <pose relative_to='gripper_base_down_right_gripper_link_joint'>0 0 0 0 -0 0</pose>
        <inertial>
          <pose>0 -0.15 0 0 -0 0</pose>
          <mass>0.001</mass>
          <inertia>
            <ixx>1.3e-06</ixx>
            <ixy>0</ixy>
            <ixz>0</ixz>
            <iyy>4.5e-08</iyy>
            <iyz>0</iyz>
            <izz>1.3e-06</izz>
          </inertia>
        </inertial>
        <collision name='down_right_gripper_link_link_collision'>
          <pose>0 -0.15 0 0 -0 0</pose>
          <geometry>
            <box>
              <size>0.08 0.4 0.04</size>
            </box>
          </geometry>
          <surface>
            <contact>
              <ode/>
            </contact>
            <friction>
              <ode/>
              <torsional>
                <ode/>
              </torsional>
            </friction>
            <bounce/>
          </surface>
          <max_contacts>10</max_contacts>
        </collision>
        <visual name='down_right_gripper_link_link_visual'>
          <pose>0.04 0.04 0 0 -0 3.14</pose>
          <geometry>
            <mesh>
              <scale>0.01 0.01 0.01</scale>
              <uri>model://sort_robotic_arm_description/meshes/Arm_Gripper/Gripper_Link.STL</uri>
            </mesh>
          </geometry>
          <material>
            <script>
              <name>Gazebo/Yellow</name>
              <uri>file://media/materials/scripts/gazebo.material</uri>
            </script>
          </material>
        </visual>
        <self_collide>0</self_collide>
        <enable_wind>0</enable_wind>
        <kinematic>0</kinematic>
      </link>
      <joint name='gripper_base_gear1_joint' type='revolute'>
        <pose relative_to='gripper_base_link'>-0.09 -0.36 0.14 0 -0 3.05</pose>
        <parent>gripper_base_link</parent>
        <child>gear1_link</child>
        <axis>
          <xyz>0 0 -1</xyz>
          <limit>
            <lower>-1e+16</lower>
            <upper>1e+16</upper>
          </limit>
          <dynamics>
            <spring_reference>0</spring_reference>
            <spring_stiffness>0</spring_stiffness>
          </dynamics>
        </axis>
      </joint>
      <link name='gear1_link'>
        <pose relative_to='gripper_base_gear1_joint'>0 0 0 0 -0 0</pose>
        <inertial>
          <pose>-0.01 0 0 0 -0 0</pose>
          <mass>0.00332</mass>
          <inertia>
            <ixx>5e-05</ixx>
            <ixy>0</ixy>
            <ixz>0</ixz>
            <iyy>0.0001</iyy>
            <iyz>0</iyz>
            <izz>4.6e-05</izz>
          </inertia>
        </inertial>
        <collision name='gear1_link_collision'>
          <pose>-0.01 0 0 0 -0 0</pose>
          <geometry>
            <cylinder>
              <length>0.04</length>
              <radius>0.133</radius>
            </cylinder>
          </geometry>
          <surface>
            <contact>
              <ode/>
            </contact>
            <friction>
              <ode/>
              <torsional>
                <ode/>
              </torsional>
            </friction>
            <bounce/>
          </surface>
          <max_contacts>10</max_contacts>
        </collision>
        <visual name='gear1_link_visual'>
          <pose>0.1209 -0.1463 0 3.14159 -1.57079 3.14159</pose>
          <geometry>
            <mesh>
              <scale>0.01 0.01 0.01</scale>
              <uri>model://sort_robotic_arm_description/meshes/Arm_Gripper/Gear1.STL</uri>
            </mesh>
          </geometry>
          <material>
            <script>
              <name>Gazebo/Yellow</name>
              <uri>file://media/materials/scripts/gazebo.material</uri>
            </script>
          </material>
        </visual>
        <self_collide>0</self_collide>
        <enable_wind>0</enable_wind>
        <kinematic>0</kinematic>
      </link>
      <joint name='gear1_left_gripper_joint' type='revolute'>
        <pose relative_to='gear1_link'>0 0.3075 0 0 -0 0.45</pose>
        <parent>gear1_link</parent>
        <child>left_gripper_link</child>
        <axis>
          <xyz>0 0 1</xyz>
          <limit>
            <lower>-1e+16</lower>
            <upper>1e+16</upper>
          </limit>
          <dynamics>
            <spring_reference>0</spring_reference>
            <spring_stiffness>0</spring_stiffness>
          </dynamics>
        </axis>
      </joint>
      <link name='left_gripper_link'>
        <pose relative_to='gear1_left_gripper_joint'>0 0 0 0 -0 0</pose>
        <inertial>
          <pose>0 0.28 0 3.14159 0.001593 3.14159</pose>
          <mass>0.00589</mass>
          <inertia>
            <ixx>1.8e-05</ixx>
            <ixy>0</ixy>
            <ixz>0</ixz>
            <iyy>1.6e-06</iyy>
            <iyz>0</iyz>
            <izz>1.9e-05</izz>
          </inertia>
        </inertial>
        <collision name='left_gripper_link_collision'>
          <pose>0.153 -0.05 0 3.14159 0.001593 3.14159</pose>
          <geometry>
            <mesh>
              <scale>0.01 0.01 0.01</scale>
              <uri>model://sort_robotic_arm_description/meshes/Arm_Gripper/Gripper.STL</uri>
            </mesh>
          </geometry>
          <surface>
            <contact>
              <ode/>
            </contact>
            <friction>
              <ode/>
              <torsional>
                <ode/>
              </torsional>
            </friction>
            <bounce/>
          </surface>
          <max_contacts>10</max_contacts>
        </collision>
        <visual name='left_gripper_link_visual'>
          <pose>0.153 -0.05 0 3.14159 0.001593 3.14159</pose>
          <geometry>
            <mesh>
              <scale>0.01 0.01 0.01</scale>
              <uri>model://sort_robotic_arm_description/meshes/Arm_Gripper/Gripper.STL</uri>
            </mesh>
          </geometry>
          <material>
            <script>
              <name>Gazebo/Yellow</name>
              <uri>file://media/materials/scripts/gazebo.material</uri>
            </script>
          </material>
        </visual>
        <self_collide>0</self_collide>
        <enable_wind>0</enable_wind>
        <kinematic>0</kinematic>
      </link>
      <joint name='micro_servo3_gear2_joint' type='revolute'>
        <pose relative_to='gripper_base_link'>0.179 -0.36 0.14 0 -0 0</pose>
        <parent>gripper_base_link</parent>
        <child>gear2_link</child>
        <axis>
          <xyz>0 0 1</xyz>
          <limit>
            <lower>0.1</lower>
            <upper>1.3</upper>
            <effort>10</effort>
            <velocity>1</velocity>
          </limit>
          <dynamics>
            <spring_reference>0</spring_reference>
            <spring_stiffness>0</spring_stiffness>
          </dynamics>
        </axis>
      </joint>
      <link name='gear2_link'>
        <pose relative_to='micro_servo3_gear2_joint'>0 0 0 0 -0 0</pose>
        <inertial>
          <pose>-0.01 0 0 0 -0 0</pose>
          <mass>0.00277</mass>
          <inertia>
            <ixx>5e-05</ixx>
            <ixy>0</ixy>
            <ixz>0</ixz>
            <iyy>0.0001</iyy>
            <iyz>0</iyz>
            <izz>4.6e-05</izz>
          </inertia>
        </inertial>
        <collision name='gear2_link_collision'>
          <pose>-0.01 0 0 0 -0 0</pose>
          <geometry>
            <cylinder>
              <length>0.04</length>
              <radius>0.133</radius>
            </cylinder>
          </geometry>
          <surface>
            <contact>
              <ode/>
            </contact>
            <friction>
              <ode/>
              <torsional>
                <ode/>
              </torsional>
            </friction>
            <bounce/>
          </surface>
          <max_contacts>10</max_contacts>
        </collision>
        <visual name='gear2_link_visual'>
          <pose>0.1209 -0.3475 0 3.14159 -1.57079 3.14159</pose>
          <geometry>
            <mesh>
              <scale>0.01 0.01 0.01</scale>
              <uri>model://sort_robotic_arm_description/meshes/Arm_Gripper/Gear2.STL</uri>
            </mesh>
          </geometry>
          <material>
            <script>
              <name>Gazebo/Yellow</name>
              <uri>file://media/materials/scripts/gazebo.material</uri>
            </script>
          </material>
        </visual>
        <self_collide>0</self_collide>
        <enable_wind>0</enable_wind>
        <kinematic>0</kinematic>
      </link>
      <joint name='gear2_right_gripper_joint' type='revolute'>
        <pose relative_to='gear2_link'>0 -0.3075 0 0 -0 2.78319</pose>
        <parent>gear2_link</parent>
        <child>right_gripper_link</child>
        <axis>
          <xyz>0 0 -1</xyz>
          <limit>
            <lower>-1e+16</lower>
            <upper>1e+16</upper>
          </limit>
          <dynamics>
            <spring_reference>0</spring_reference>
            <spring_stiffness>0</spring_stiffness>
          </dynamics>
        </axis>
      </joint>
      <link name='right_gripper_link'>
        <pose relative_to='gear2_right_gripper_joint'>0 0 0 0 -0 0</pose>
        <inertial>
          <pose>0 0.28 0 0 -0 0</pose>
          <mass>0.00589</mass>
          <inertia>
            <ixx>1.8e-05</ixx>
            <ixy>0</ixy>
            <ixz>0</ixz>
            <iyy>1.6e-06</iyy>
            <iyz>0</iyz>
            <izz>1.9e-05</izz>
          </inertia>
        </inertial>
        <collision name='right_gripper_link_collision'>
          <pose>-0.1462 -0.05 -0.085 0 -0 0</pose>
          <geometry>
            <mesh>
              <scale>0.01 0.01 0.01</scale>
              <uri>model://sort_robotic_arm_description/meshes/Arm_Gripper/Gripper.STL</uri>
            </mesh>
          </geometry>
          <surface>
            <contact>
              <ode/>
            </contact>
            <friction>
              <ode/>
              <torsional>
                <ode/>
              </torsional>
            </friction>
            <bounce/>
          </surface>
          <max_contacts>10</max_contacts>
        </collision>
        <visual name='right_gripper_link_visual'>
          <pose>-0.1462 -0.05 -0.085 0 -0 0</pose>
          <geometry>
            <mesh>
              <scale>0.01 0.01 0.01</scale>
              <uri>model://sort_robotic_arm_description/meshes/Arm_Gripper/Gripper.STL</uri>
            </mesh>
          </geometry>
          <material>
            <script>
              <name>Gazebo/Yellow</name>
              <uri>file://media/materials/scripts/gazebo.material</uri>
            </script>
          </material>
        </visual>
        <self_collide>0</self_collide>
        <enable_wind>0</enable_wind>
        <kinematic>0</kinematic>
      </link>
      <joint name='gripper_base_up_left_gripper_link_joint' type='revolute'>
        <pose relative_to='gripper_base_link'>-0.01 -0.56 0.14 0 0 -0.1</pose>
        <parent>gripper_base_link</parent>
        <child>up_left_gripper_link_link</child>
        <axis>
          <xyz>0 0 -1</xyz>
          <limit>
            <lower>-1e+16</lower>
            <upper>1e+16</upper>
          </limit>
          <dynamics>
            <spring_reference>0</spring_reference>
            <spring_stiffness>0</spring_stiffness>
          </dynamics>
        </axis>
      </joint>
      <link name='up_left_gripper_link_link'>
        <pose relative_to='gripper_base_up_left_gripper_link_joint'>0 0 0 0 -0 0</pose>
        <inertial>
          <pose>0 -0.15 0 0 -0 0</pose>
          <mass>0.001</mass>
          <inertia>
            <ixx>1.3e-06</ixx>
            <ixy>0</ixy>
            <ixz>0</ixz>
            <iyy>4.5e-08</iyy>
            <iyz>0</iyz>
            <izz>1.3e-06</izz>
          </inertia>
        </inertial>
        <collision name='up_left_gripper_link_link_collision'>
          <pose>0 -0.15 0 0 -0 0</pose>
          <geometry>
            <box>
              <size>0.08 0.4 0.04</size>
            </box>
          </geometry>
          <surface>
            <contact>
              <ode/>
            </contact>
            <friction>
              <ode/>
              <torsional>
                <ode/>
              </torsional>
            </friction>
            <bounce/>
          </surface>
          <max_contacts>10</max_contacts>
        </collision>
        <visual name='up_left_gripper_link_link_visual'>
          <pose>0.04 0.04 0 0 -0 3.14</pose>
          <geometry>
            <mesh>
              <scale>0.01 0.01 0.01</scale>
              <uri>model://sort_robotic_arm_description/meshes/Arm_Gripper/Gripper_Link.STL</uri>
            </mesh>
          </geometry>
          <material>
            <script>
              <name>Gazebo/Yellow</name>
              <uri>file://media/materials/scripts/gazebo.material</uri>
            </script>
          </material>
        </visual>
        <self_collide>0</self_collide>
        <enable_wind>0</enable_wind>
        <kinematic>0</kinematic>
      </link>
      <joint name='gripper_base_up_right_gripper_link_joint' type='revolute'>
        <pose relative_to='gripper_base_link'>0.09 -0.56 0.14 0 -0 0</pose>
        <parent>gripper_base_link</parent>
        <child>up_right_gripper_link_link</child>
        <axis>
          <xyz>0 0 1</xyz>
          <limit>
            <lower>-1e+16</lower>
            <upper>1e+16</upper>
          </limit>
          <dynamics>
            <spring_reference>0</spring_reference>
            <spring_stiffness>0</spring_stiffness>
          </dynamics>
        </axis>
      </joint>
      <link name='up_right_gripper_link_link'>
        <pose relative_to='gripper_base_up_right_gripper_link_joint'>0 0 0 0 -0 0</pose>
        <inertial>
          <pose>0 -0.15 0.02 0 -0 0</pose>
          <mass>0.001</mass>
          <inertia>
            <ixx>1.3e-06</ixx>
            <ixy>0</ixy>
            <ixz>0</ixz>
            <iyy>4.5e-08</iyy>
            <iyz>0</iyz>
            <izz>1.3e-06</izz>
          </inertia>
        </inertial>
        <collision name='up_right_gripper_link_link_collision'>
          <pose>0 -0.15 0.02 0 -0 0</pose>
          <geometry>
            <box>
              <size>0.08 0.4 0.04</size>
            </box>
          </geometry>
          <surface>
            <contact>
              <ode/>
            </contact>
            <friction>
              <ode/>
              <torsional>
                <ode/>
              </torsional>
            </friction>
            <bounce/>
          </surface>
          <max_contacts>10</max_contacts>
        </collision>
        <visual name='up_right_gripper_link_link_visual'>
          <pose>0.04 0.04 0 0 -0 3.14</pose>
          <geometry>
            <mesh>
              <scale>0.01 0.01 0.01</scale>
              <uri>model://sort_robotic_arm_description/meshes/Arm_Gripper/Gripper_Link.STL</uri>
            </mesh>
          </geometry>
          <material>
            <script>
              <name>Gazebo/Yellow</name>
              <uri>file://media/materials/scripts/gazebo.material</uri>
            </script>
          </material>
        </visual>
        <self_collide>0</self_collide>
        <enable_wind>0</enable_wind>
        <kinematic>0</kinematic>
      </link>
      <static>0</static>
      <plugin name='gazebo_ros2_control' filename='libgazebo_ros2_control.so'>
        <parameters>/home/daniel/ros2_ws/install/sort_robotic_arm_description/share/sort_robotic_arm_description/yaml/config_yaml.yaml</parameters>
      </plugin>
      <pose>0 0 0 0 -0 0</pose>
    </model>
    <model name='measure_cube'>
      <link name='link_0'>
        <inertial>
          <mass>1</mass>
          <inertia>
            <ixx>0.166667</ixx>
            <ixy>0</ixy>
            <ixz>0</ixz>
            <iyy>0.166667</iyy>
            <iyz>0</iyz>
            <izz>0.166667</izz>
          </inertia>
          <pose>0 -1 0 0 -0 0</pose>
        </inertial>
        <pose>0 -1 0 0 -0 0</pose>
        <gravity>1</gravity>
        <self_collide>0</self_collide>
        <kinematic>0</kinematic>
        <enable_wind>0</enable_wind>
        <visual name='visual'>
          <pose>0 -1 -0.5 0 -0 0</pose>
          <geometry>
            <box>
              <size>1.2 1.2 0.01</size>
            </box>
          </geometry>
          <material>
            <lighting>1</lighting>
            <script>
              <uri>file://media/materials/scripts/gazebo.material</uri>
              <name>Gazebo/Blue</name>
            </script>
            <shader type='pixel'>
              <normal_map>__default__</normal_map>
            </shader>
            <ambient>0 0 1 1</ambient>
            <diffuse>0 0 1 1</diffuse>
            <specular>0.01 0.01 0.01 1</specular>
            <emissive>0 0 0 1</emissive>
          </material>
          <transparency>0</transparency>
          <cast_shadows>1</cast_shadows>
        </visual>
        <collision name='collision'>
          <laser_retro>0</laser_retro>
          <max_contacts>10</max_contacts>
          <pose>0 -1 -0.5 0 -0 0</pose>
          <geometry>
            <box>
              <size>1.2 1.2 0.01</size>
            </box>
          </geometry>
          <surface>
            <friction>
              <ode>
                <mu>1</mu>
                <mu2>1</mu2>
                <fdir1>0 0 0</fdir1>
                <slip1>0</slip1>
                <slip2>0</slip2>
              </ode>
              <torsional>
                <coefficient>1</coefficient>
                <patch_radius>0</patch_radius>
                <surface_radius>0</surface_radius>
                <use_patch_radius>1</use_patch_radius>
                <ode>
                  <slip>0</slip>
                </ode>
              </torsional>
            </friction>
            <bounce>
              <restitution_coefficient>0</restitution_coefficient>
              <threshold>1e+06</threshold>
            </bounce>
            <contact>
              <collide_without_contact>0</collide_without_contact>
              <collide_without_contact_bitmask>1</collide_without_contact_bitmask>
              <collide_bitmask>1</collide_bitmask>
              <ode>
                <soft_cfm>0</soft_cfm>
                <soft_erp>0.2</soft_erp>
                <kp>1e+13</kp>
                <kd>1</kd>
                <max_vel>0.01</max_vel>
                <min_depth>0</min_depth>
              </ode>
              <bullet>
                <split_impulse>1</split_impulse>
                <split_impulse_penetration_threshold>-0.01</split_impulse_penetration_threshold>
                <soft_cfm>0</soft_cfm>
                <soft_erp>0.2</soft_erp>
                <kp>1e+13</kp>
                <kd>1</kd>
              </bullet>
            </contact>
          </surface>
        </collision>
      </link>
      <static>0</static>
      <allow_auto_disable>1</allow_auto_disable>
      <pose>0.046434 -1.33265 0.5 0 -0 0</pose>
    </model>
  </world>
</sdf>
