<?xml version="1.0"?>
<robot xmlns:xacro="http://www.ros.org/wiki/xacro">

    <material name="blue">
        <color rgba="0 0 0.5 1" />
    </material>

    <material name="yellow">
        <color rgba="1 1 0 1" />
    </material>

    <material name="grey">
        <color rgba="0.5 0.5 0.5 1" />
    </material>

    <material name="red">
        <color rgba="1 0.2 0 1" />
    </material>

    <xacro:macro name="tower_link" params="name m l w h xyz rpy">
        <link name="${name}_tower_link"> 
            <visual>
                <geometry>
                    <box size="${l} ${w} ${h}"/>
                </geometry>
                <origin xyz="${xyz}" rpy="${rpy}"/>
                <material name="blue" />
            </visual>
            <collision>
                <geometry>
                    <box size="${l} ${w} ${h}" />
                </geometry>
                <origin xyz="${xyz}" rpy="${rpy}"/>
            </collision>
            <inertial>
                <origin xyz="${xyz}" rpy="${rpy}"/>
                <mass value="${m}" />
                <inertia ixx="${(m/12) * (h*h + l*l)}" ixy="0" ixz="0"
                        iyy="${(m/12) * (w*w + l*l)}" iyz="0"
                        izz="${(m/12) * (h*h + w*w)}" />
            </inertial>
        </link>
    </xacro:macro>

    <xacro:macro name="box_link" params="name file xyz_visual rpy_visual size mass color
                                      xyz_collision rpy_collision ixx ixy ixz iyy iyz izz" > 
        <link name="${name}_link"> 
            <visual>
                <geometry>
                    <mesh filename="${file}" scale="0.01 0.01 0.01"/>
                </geometry>
                <origin xyz="${xyz_visual}" rpy="${rpy_visual}"/>
                <material name="${color}" />
            </visual>
            <collision>
                <geometry>
                    <box size="${size}" />
                </geometry>
                <origin xyz="${xyz_collision}" rpy="${rpy_collision}"/>
            </collision>
            <inertial>
                <origin xyz="${xyz_collision}" rpy="${rpy_collision}"/>
                <mass value="${mass}" />
                <inertia ixx="${ixx}" ixy="${ixy}" ixz="${ixz}"
                        iyy="${iyy}" iyz="${iyz}"
                        izz="${izz}" />
            </inertial>
        </link>
    </xacro:macro>

    <xacro:macro name="cylinder_link" params="name file xyz_visual rpy_visual radius length
                            mass color xyz_collision rpy_collision ixx ixy ixz iyy iyz izz" > 
        <link name="${name}_link"> 
            <visual>
                <geometry>
                    <mesh filename="${file}" scale="0.01 0.01 0.01"/>
                </geometry>
                <origin xyz="${xyz_visual}" rpy="${rpy_visual}"/>
                <material name="${color}" />
            </visual>
            <collision>
                <geometry>
                    <cylinder radius="${radius}" length="${length}" />
                </geometry>
                <origin xyz="${xyz_collision}" rpy="${rpy_collision}"/>
            </collision>
            <inertial>
                <origin xyz="${xyz_collision}" rpy="${rpy_collision}"/>
                <mass value="${mass}" />
                <inertia ixx="${ixx}" ixy="${ixy}" ixz="${ixz}"
                        iyy="${iyy}" iyz="${iyz}"
                        izz="${izz}" />
            </inertial>
        </link>
    </xacro:macro>

    <xacro:macro name="fixed_joint" params="name parent child xyz rpy" > 
        <joint name="${name}_joint" type="fixed">
            <parent link="${parent}"/>
            <child link="${child}"/>
            <origin xyz="${xyz}" rpy="${rpy}"/>
        </joint>
    </xacro:macro>

    <xacro:macro name="continuous_joint" params="name parent child xyz rpy xyz_rotate" > 
        <joint name="${name}_joint" type="continuous">
            <parent link="${parent}"/>
            <child link="${child}"/>
            <origin xyz="${xyz}" rpy="${rpy}"/>
            <axis xyz="${xyz_rotate}"/>
        </joint>
    </xacro:macro>

    <xacro:macro name="mimic_continuous_joint" params="name parent child xyz rpy xyz_rotate" > 
        <joint name="${name}_joint" type="continuous">
            <parent link="${parent}"/>
            <child link="${child}"/>
            <origin xyz="${xyz}" rpy="${rpy}"/>
            <axis xyz="${xyz_rotate}"/>
            <mimic joint="micro_servo3_gear2_joint" multiplier="1.0" offset="0.0"/>
        </joint>
    </xacro:macro>

    <xacro:macro name="revolute_joint" params="name parent child xyz rpy xyz_rotate
                                               lower upper effort velocity" > 
        <joint name="${name}_joint" type="revolute">
            <parent link="${parent}"/>
            <child link="${child}"/>
            <origin xyz="${xyz}" rpy="${rpy}"/>
            <axis xyz="${xyz_rotate}"/>
            <limit lower="${lower}" upper="${upper}" effort="${effort}" velocity="${velocity}"/>
        </joint>
    </xacro:macro>
</robot>